 * Serving Flask app 'website'
 * Debug mode: on
85.90.246.159 - - [09/May/2024 23:09:58] code 400, message Bad request version ('À\x14À')
45.79.181.179 - - [10/May/2024 00:03:25] code 400, message Bad request version ('À\x14À')
20.3.131.163 - - [10/May/2024 02:11:33] code 400, message Bad request version ('RTSP/1.0')
20.3.131.163 - - [10/May/2024 02:11:34] code 400, message Bad HTTP/0.9 request type ('l\x00')
20.3.131.163 - - [10/May/2024 02:15:37] code 400, message Bad request version ('\x00/\x00')
192.155.90.220 - - [10/May/2024 02:15:40] code 400, message Bad request version ('¶)ÌèZ!\x0e;æáM~\x9dÌ')
179.60.147.136 - - [10/May/2024 02:46:42] code 400, message Bad HTTP/0.9 request type ('\x03\x00\x00/*à\x00\x00\x00\x00\x00Cookie:')
78.153.140.177 - - [10/May/2024 03:42:29] code 400, message Bad request version ('¢\x19\x176þ\x17P>)ÅÒæß²ñ\x00b\x13\x02\x13\x03\x13\x01À,À0À+À/Ì©Ì¨\x00£\x00\x9f\x00¢\x00\x9eÌªÀ¯À\xadÀ$À(À')
178.79.144.158 - - [10/May/2024 06:02:53] code 400, message Bad request version ('\x00\x04\x03\x00\x01\x02\x00')
178.79.144.158 - - [10/May/2024 06:02:54] code 400, message Bad request version ('\x00\x04\x03\x00\x01\x02\x00')
178.79.144.158 - - [10/May/2024 06:02:54] code 400, message Bad request version ('\x9bòÉÄ/')
66.175.213.4 - - [10/May/2024 06:27:04] code 400, message Bad request version ('À\x14À')
80.75.212.75 - - [10/May/2024 07:30:35] code 400, message Bad request syntax ('\x05\x01\x00')
167.94.138.40 - - [10/May/2024 08:38:34] code 505, message Invalid HTTP version (2.0)
167.94.138.40 - - [10/May/2024 08:38:43] code 505, message Invalid HTTP version (2.0)
64.62.197.234 - - [10/May/2024 09:41:26] code 400, message Bad request version ('À\x14À')
Traceback (most recent call last):
  File "/usr/local/lib/python3.8/dist-packages/flask/app.py", line 1498, in __call__
    return self.wsgi_app(environ, start_response)
  File "/usr/local/lib/python3.8/dist-packages/flask_socketio/__init__.py", line 43, in __call__
    return super(_SocketIOMiddleware, self).__call__(environ,
  File "/usr/local/lib/python3.8/dist-packages/engineio/middleware.py", line 63, in __call__
    return self.engineio_app.handle_request(environ, start_response)
  File "/usr/local/lib/python3.8/dist-packages/socketio/server.py", line 430, in handle_request
    return self.eio.handle_request(environ, start_response)
  File "/usr/local/lib/python3.8/dist-packages/engineio/server.py", line 272, in handle_request
    socket = self._get_socket(sid)
  File "/usr/local/lib/python3.8/dist-packages/engineio/base_server.py", line 229, in _get_socket
    raise KeyError('Session is disconnected')
KeyError: 'Session is disconnected'
167.71.201.103 - - [10/May/2024 10:33:50] code 400, message Bad request version ('À\x13À')
185.122.204.179 - - [10/May/2024 10:51:03] code 400, message Bad HTTP/0.9 request type ('\x03\x00\x00/*à\x00\x00\x00\x00\x00Cookie:')
Traceback (most recent call last):
  File "/usr/local/lib/python3.8/dist-packages/flask/app.py", line 880, in full_dispatch_request
    rv = self.dispatch_request()
  File "/usr/local/lib/python3.8/dist-packages/flask/app.py", line 854, in dispatch_request
    self.raise_routing_exception(req)
  File "/usr/local/lib/python3.8/dist-packages/flask/app.py", line 463, in raise_routing_exception
    raise request.routing_exception  # type: ignore[misc]
  File "/usr/local/lib/python3.8/dist-packages/flask/ctx.py", line 362, in match_request
    result = self.url_adapter.match(return_rule=True)  # type: ignore
  File "/usr/local/lib/python3.8/dist-packages/werkzeug/routing/map.py", line 626, in match
    raise MethodNotAllowed(valid_methods=list(e.have_match_for)) from None
werkzeug.exceptions.MethodNotAllowed: 405 Method Not Allowed: The method is not allowed for the requested URL.

During handling of the above exception, another exception occurred:

Traceback (most recent call last):
  File "/usr/local/lib/python3.8/dist-packages/flask/app.py", line 1498, in __call__
    return self.wsgi_app(environ, start_response)
  File "/usr/local/lib/python3.8/dist-packages/flask_socketio/__init__.py", line 43, in __call__
    return super(_SocketIOMiddleware, self).__call__(environ,
  File "/usr/local/lib/python3.8/dist-packages/engineio/middleware.py", line 74, in __call__
    return self.wsgi_app(environ, start_response)
  File "/usr/local/lib/python3.8/dist-packages/flask/app.py", line 1476, in wsgi_app
    response = self.handle_exception(e)
  File "/usr/local/lib/python3.8/dist-packages/flask/app.py", line 1473, in wsgi_app
    response = self.full_dispatch_request()
  File "/usr/local/lib/python3.8/dist-packages/flask/app.py", line 882, in full_dispatch_request
    rv = self.handle_user_exception(e)
  File "/usr/local/lib/python3.8/dist-packages/flask/app.py", line 765, in handle_user_exception
    return self.handle_http_exception(e)
  File "/usr/local/lib/python3.8/dist-packages/flask/app.py", line 740, in handle_http_exception
    return self.ensure_sync(handler)(e)  # type: ignore[no-any-return]
  File "/home/azureuser/SpyNet/main.py", line 35, in exception_handler
    discord_log_backend(f'User : {current_user.username} encountered an error while trying to access {request.url} ```{error}``` <@709799648143081483>')
AttributeError: 'AnonymousUserMixin' object has no attribute 'username'
Traceback (most recent call last):
  File "/usr/local/lib/python3.8/dist-packages/flask/app.py", line 1498, in __call__
    return self.wsgi_app(environ, start_response)
  File "/usr/local/lib/python3.8/dist-packages/flask_socketio/__init__.py", line 43, in __call__
    return super(_SocketIOMiddleware, self).__call__(environ,
  File "/usr/local/lib/python3.8/dist-packages/engineio/middleware.py", line 63, in __call__
    return self.engineio_app.handle_request(environ, start_response)
  File "/usr/local/lib/python3.8/dist-packages/socketio/server.py", line 430, in handle_request
    return self.eio.handle_request(environ, start_response)
  File "/usr/local/lib/python3.8/dist-packages/engineio/server.py", line 272, in handle_request
    socket = self._get_socket(sid)
  File "/usr/local/lib/python3.8/dist-packages/engineio/base_server.py", line 229, in _get_socket
    raise KeyError('Session is disconnected')
KeyError: 'Session is disconnected'
Traceback (most recent call last):
  File "/usr/local/lib/python3.8/dist-packages/flask/app.py", line 880, in full_dispatch_request
    rv = self.dispatch_request()
  File "/usr/local/lib/python3.8/dist-packages/flask/app.py", line 854, in dispatch_request
    self.raise_routing_exception(req)
  File "/usr/local/lib/python3.8/dist-packages/flask/app.py", line 463, in raise_routing_exception
    raise request.routing_exception  # type: ignore[misc]
  File "/usr/local/lib/python3.8/dist-packages/flask/ctx.py", line 362, in match_request
    result = self.url_adapter.match(return_rule=True)  # type: ignore
  File "/usr/local/lib/python3.8/dist-packages/werkzeug/routing/map.py", line 626, in match
    raise MethodNotAllowed(valid_methods=list(e.have_match_for)) from None
werkzeug.exceptions.MethodNotAllowed: 405 Method Not Allowed: The method is not allowed for the requested URL.

During handling of the above exception, another exception occurred:

Traceback (most recent call last):
  File "/usr/local/lib/python3.8/dist-packages/flask/app.py", line 1498, in __call__
    return self.wsgi_app(environ, start_response)
  File "/usr/local/lib/python3.8/dist-packages/flask_socketio/__init__.py", line 43, in __call__
    return super(_SocketIOMiddleware, self).__call__(environ,
  File "/usr/local/lib/python3.8/dist-packages/engineio/middleware.py", line 74, in __call__
    return self.wsgi_app(environ, start_response)
  File "/usr/local/lib/python3.8/dist-packages/flask/app.py", line 1476, in wsgi_app
    response = self.handle_exception(e)
  File "/usr/local/lib/python3.8/dist-packages/flask/app.py", line 1473, in wsgi_app
    response = self.full_dispatch_request()
  File "/usr/local/lib/python3.8/dist-packages/flask/app.py", line 882, in full_dispatch_request
    rv = self.handle_user_exception(e)
  File "/usr/local/lib/python3.8/dist-packages/flask/app.py", line 765, in handle_user_exception
    return self.handle_http_exception(e)
  File "/usr/local/lib/python3.8/dist-packages/flask/app.py", line 740, in handle_http_exception
    return self.ensure_sync(handler)(e)  # type: ignore[no-any-return]
  File "/home/azureuser/SpyNet/main.py", line 35, in exception_handler
    discord_log_backend(f'User : {current_user.username} encountered an error while trying to access {request.url} ```{error}``` <@709799648143081483>')
AttributeError: 'AnonymousUserMixin' object has no attribute 'username'
Invalid session cJ_f_lh86Hc2B1i3AABe (further occurrences of this error will be logged with level INFO)
199.45.154.26 - - [10/May/2024 14:05:34] code 505, message Invalid HTTP version (2.0)
199.45.154.26 - - [10/May/2024 14:05:39] code 505, message Invalid HTTP version (2.0)
Traceback (most recent call last):
  File "/usr/local/lib/python3.8/dist-packages/flask/app.py", line 880, in full_dispatch_request
    rv = self.dispatch_request()
  File "/usr/local/lib/python3.8/dist-packages/flask/app.py", line 854, in dispatch_request
    self.raise_routing_exception(req)
  File "/usr/local/lib/python3.8/dist-packages/flask/app.py", line 463, in raise_routing_exception
    raise request.routing_exception  # type: ignore[misc]
  File "/usr/local/lib/python3.8/dist-packages/flask/ctx.py", line 362, in match_request
    result = self.url_adapter.match(return_rule=True)  # type: ignore
  File "/usr/local/lib/python3.8/dist-packages/werkzeug/routing/map.py", line 626, in match
    raise MethodNotAllowed(valid_methods=list(e.have_match_for)) from None
werkzeug.exceptions.MethodNotAllowed: 405 Method Not Allowed: The method is not allowed for the requested URL.

During handling of the above exception, another exception occurred:

Traceback (most recent call last):
  File "/usr/local/lib/python3.8/dist-packages/flask/app.py", line 1498, in __call__
    return self.wsgi_app(environ, start_response)
  File "/usr/local/lib/python3.8/dist-packages/flask_socketio/__init__.py", line 43, in __call__
    return super(_SocketIOMiddleware, self).__call__(environ,
  File "/usr/local/lib/python3.8/dist-packages/engineio/middleware.py", line 74, in __call__
    return self.wsgi_app(environ, start_response)
  File "/usr/local/lib/python3.8/dist-packages/flask/app.py", line 1476, in wsgi_app
    response = self.handle_exception(e)
  File "/usr/local/lib/python3.8/dist-packages/flask/app.py", line 1473, in wsgi_app
    response = self.full_dispatch_request()
  File "/usr/local/lib/python3.8/dist-packages/flask/app.py", line 882, in full_dispatch_request
    rv = self.handle_user_exception(e)
  File "/usr/local/lib/python3.8/dist-packages/flask/app.py", line 765, in handle_user_exception
    return self.handle_http_exception(e)
  File "/usr/local/lib/python3.8/dist-packages/flask/app.py", line 740, in handle_http_exception
    return self.ensure_sync(handler)(e)  # type: ignore[no-any-return]
  File "/home/azureuser/SpyNet/main.py", line 35, in exception_handler
    discord_log_backend(f'User : {current_user.username} encountered an error while trying to access {request.url} ```{error}``` <@709799648143081483>')
AttributeError: 'AnonymousUserMixin' object has no attribute 'username'
172.104.11.46 - - [10/May/2024 14:33:34] code 400, message Bad request version ('À\x14À')
Traceback (most recent call last):
  File "/usr/local/lib/python3.8/dist-packages/flask/app.py", line 1498, in __call__
    return self.wsgi_app(environ, start_response)
  File "/usr/local/lib/python3.8/dist-packages/flask_socketio/__init__.py", line 43, in __call__
    return super(_SocketIOMiddleware, self).__call__(environ,
  File "/usr/local/lib/python3.8/dist-packages/engineio/middleware.py", line 63, in __call__
    return self.engineio_app.handle_request(environ, start_response)
  File "/usr/local/lib/python3.8/dist-packages/socketio/server.py", line 430, in handle_request
    return self.eio.handle_request(environ, start_response)
  File "/usr/local/lib/python3.8/dist-packages/engineio/server.py", line 272, in handle_request
    socket = self._get_socket(sid)
  File "/usr/local/lib/python3.8/dist-packages/engineio/base_server.py", line 229, in _get_socket
    raise KeyError('Session is disconnected')
KeyError: 'Session is disconnected'
Traceback (most recent call last):
  File "/usr/local/lib/python3.8/dist-packages/flask/app.py", line 880, in full_dispatch_request
    rv = self.dispatch_request()
  File "/usr/local/lib/python3.8/dist-packages/flask/app.py", line 854, in dispatch_request
    self.raise_routing_exception(req)
  File "/usr/local/lib/python3.8/dist-packages/flask/app.py", line 463, in raise_routing_exception
    raise request.routing_exception  # type: ignore[misc]
  File "/usr/local/lib/python3.8/dist-packages/flask/ctx.py", line 362, in match_request
    result = self.url_adapter.match(return_rule=True)  # type: ignore
  File "/usr/local/lib/python3.8/dist-packages/werkzeug/routing/map.py", line 626, in match
    raise MethodNotAllowed(valid_methods=list(e.have_match_for)) from None
werkzeug.exceptions.MethodNotAllowed: 405 Method Not Allowed: The method is not allowed for the requested URL.

During handling of the above exception, another exception occurred:

Traceback (most recent call last):
  File "/usr/local/lib/python3.8/dist-packages/flask/app.py", line 1498, in __call__
    return self.wsgi_app(environ, start_response)
  File "/usr/local/lib/python3.8/dist-packages/flask_socketio/__init__.py", line 43, in __call__
    return super(_SocketIOMiddleware, self).__call__(environ,
  File "/usr/local/lib/python3.8/dist-packages/engineio/middleware.py", line 74, in __call__
    return self.wsgi_app(environ, start_response)
  File "/usr/local/lib/python3.8/dist-packages/flask/app.py", line 1476, in wsgi_app
    response = self.handle_exception(e)
  File "/usr/local/lib/python3.8/dist-packages/flask/app.py", line 1473, in wsgi_app
    response = self.full_dispatch_request()
  File "/usr/local/lib/python3.8/dist-packages/flask/app.py", line 882, in full_dispatch_request
    rv = self.handle_user_exception(e)
  File "/usr/local/lib/python3.8/dist-packages/flask/app.py", line 765, in handle_user_exception
    return self.handle_http_exception(e)
  File "/usr/local/lib/python3.8/dist-packages/flask/app.py", line 740, in handle_http_exception
    return self.ensure_sync(handler)(e)  # type: ignore[no-any-return]
  File "/home/azureuser/SpyNet/main.py", line 35, in exception_handler
    discord_log_backend(f'User : {current_user.username} encountered an error while trying to access {request.url} ```{error}``` <@709799648143081483>')
AttributeError: 'AnonymousUserMixin' object has no attribute 'username'
172.105.128.12 - - [10/May/2024 16:16:57] code 400, message Bad request version ('À\x14À')
