 * Serving Flask app 'website'
 * Debug mode: on
154.213.184.23 - - [12/Nov/2024 06:10:58] code 400, message Bad request syntax ('\x04\x01\x01»-?(\x81\x00')
45.79.181.94 - - [12/Nov/2024 07:59:10] code 400, message Bad request syntax ('\x16\x03\x01\x00î\x01\x00\x00ê\x03\x03ì')
152.42.219.47 - - [12/Nov/2024 08:02:41] code 400, message Bad request version ('À\x13À')
159.223.67.34 - - [12/Nov/2024 08:02:44] code 400, message Bad request version ('À\x13À')
167.94.145.97 - - [12/Nov/2024 08:14:52] code 505, message Invalid HTTP version (2.0)
198.235.24.123 - - [12/Nov/2024 11:08:30] code 400, message Bad request version ('À\x13À')
198.235.24.123 - - [12/Nov/2024 11:08:30] code 400, message Bad request version ('À(À$À\x14À')
198.235.24.131 - - [12/Nov/2024 13:52:21] code 400, message Bad request version ('À\x13À')
198.235.24.131 - - [12/Nov/2024 13:52:21] code 400, message Bad request version ('À(À$À\x14À')
172.104.11.46 - - [12/Nov/2024 14:20:40] code 400, message Bad request version ('À\x13À')
152.42.214.140 - - [12/Nov/2024 16:02:55] code 400, message Bad request version ('À\x13À')
152.42.174.244 - - [12/Nov/2024 16:03:00] code 400, message Bad request version ('À\x13À')
65.49.1.95 - - [12/Nov/2024 16:03:58] code 400, message Bad request syntax ('\x16\x03\x01\x00{\x01\x00\x00w\x03\x03\x88i±l\x84xì')
78.153.140.223 - - [12/Nov/2024 16:46:43] code 400, message Bad request syntax ('\x16\x03\x01\x00¬\x01\x00\x00¨\x03\x03\x99©äí\x96qÐ\x1a:K\x99èa¡t5VV\\4\xado3®^Ý\x18\x9e\x93@\x00Ð\x00\x008À,À')
174.138.61.44 - - [12/Nov/2024 18:07:14] code 400, message Bad request version ("x64|'|'|No|'|'|S17|'|'|..|'|'|SW5ib3ggLSBPdXRsb29rIERhdGEgRmlsZSAtIE1pY3Jvc29mdCBPdXRsb29rAA==|'|'|")
5.8.11.202 - - [12/Nov/2024 18:28:55] code 400, message Bad request version ("¯nãY»bhlÿ(=':©\x82ÙoÈ¢×\x93\x98´ï\x80å¹\x90\x00(À")
78.153.140.224 - - [12/Nov/2024 19:42:44] code 400, message Bad HTTP/0.9 request type ("\x16\x03\x01\x00¬\x01\x00\x00¨\x03\x03Á¹\x99@jÀúzk\x9cªñV'-IÉ")
93.174.93.12 - - [12/Nov/2024 20:11:12] code 400, message Bad request version ("¯nãY»bhlÿ(=':©\x82ÙoÈ¢×\x93\x98´ï\x80å¹\x90\x00(À")
185.208.156.160 - - [12/Nov/2024 20:31:24] code 400, message Bad request version ('OÐ\x17íøfã')
156.67.104.159 - - [12/Nov/2024 21:36:59] code 400, message Bad request version ('H#Î/7&k4\x82gþe¢ò+\x01P\x9bê')
185.91.127.43 - - [12/Nov/2024 22:04:03] code 400, message Bad request syntax ('\x05\x01\x00')
156.67.104.159 - - [12/Nov/2024 22:06:59] code 400, message Bad request syntax ('\x16\x03\x01\x02\x00\x01\x00\x01ü\x03\x03!\x9c59TèóÏ8Ìø\x1a\x1a\x9b?Ø«\x01?f²§')
Invalid session kXU1jWHT5sz_4CEyAAAE (further occurrences of this error will be logged with level INFO)
5.8.11.202 - - [12/Nov/2024 22:34:00] code 400, message Bad request version ("¯nãY»bhlÿ(=':©\x82ÙoÈ¢×\x93\x98´ï\x80å¹\x90\x00(À")
Traceback (most recent call last):
  File "/usr/local/lib/python3.10/dist-packages/flask/app.py", line 1498, in __call__
    return self.wsgi_app(environ, start_response)
  File "/usr/local/lib/python3.10/dist-packages/flask_socketio/__init__.py", line 43, in __call__
    return super(_SocketIOMiddleware, self).__call__(environ,
  File "/usr/local/lib/python3.10/dist-packages/engineio/middleware.py", line 63, in __call__
    return self.engineio_app.handle_request(environ, start_response)
  File "/usr/local/lib/python3.10/dist-packages/socketio/server.py", line 433, in handle_request
    return self.eio.handle_request(environ, start_response)
  File "/usr/local/lib/python3.10/dist-packages/engineio/server.py", line 292, in handle_request
    socket = self._get_socket(sid)
  File "/usr/local/lib/python3.10/dist-packages/engineio/base_server.py", line 229, in _get_socket
    raise KeyError('Session is disconnected')
KeyError: 'Session is disconnected'
152.42.174.244 - - [13/Nov/2024 00:02:47] code 400, message Bad request version ('À\x13À')
152.42.243.206 - - [13/Nov/2024 00:02:53] code 400, message Bad request version ('À\x13À')
137.184.166.236 - - [13/Nov/2024 00:40:13] code 400, message Bad request syntax ('\x00\x0e8\x18N°ÖÛ¶\x16\x96\x00\x00\x00\x00\x00')
45.79.181.223 - - [13/Nov/2024 00:48:19] code 400, message Bad request syntax ('\x16\x03\x01\x00î\x01\x00\x00ê\x03\x03G\x96\x80êr?Ã\x10ï\x95\x86Æ\x00¬Kc*O')
Couldn't retrieve service cert
b'{"success":false,"code":11107,"message":"Couldn\'t verify your request.."}'
172.104.11.51 - - [13/Nov/2024 02:24:30] code 400, message Bad request syntax ('\x16\x03\x01\x00î\x01\x00\x00ê\x03\x03\x99')
Invalid session PW1zSNhmP3Z9IcTdAAAg (further occurrences of this error will be logged with level INFO)
198.235.24.150 - - [13/Nov/2024 02:26:51] code 400, message Bad request syntax ('\x16\x03\x01\x00î\x01\x00\x00ê\x03\x03´\x07Dý\x9a=¾ØÛ')
198.235.24.150 - - [13/Nov/2024 02:26:51] code 400, message Bad request version ('À(À$À\x14À')
185.91.127.43 - - [13/Nov/2024 03:07:02] code 400, message Bad request syntax ('\x05\x01\x00')
93.174.93.12 - - [13/Nov/2024 06:27:10] code 400, message Bad request version ("¯nãY»bhlÿ(=':©\x82ÙoÈ¢×\x93\x98´ï\x80å¹\x90\x00(À")
179.43.168.146 - - [13/Nov/2024 06:29:34] code 400, message Bad request version ('S_')
152.42.219.47 - - [13/Nov/2024 08:02:51] code 400, message Bad request version ('\x90Øt\x00\x97NsOêÏ©')
159.223.67.34 - - [13/Nov/2024 08:02:57] code 400, message Bad request version ('À\x13À')
Traceback (most recent call last):
  File "/usr/local/lib/python3.10/dist-packages/flask/app.py", line 1498, in __call__
    return self.wsgi_app(environ, start_response)
  File "/usr/local/lib/python3.10/dist-packages/flask_socketio/__init__.py", line 43, in __call__
    return super(_SocketIOMiddleware, self).__call__(environ,
  File "/usr/local/lib/python3.10/dist-packages/engineio/middleware.py", line 63, in __call__
    return self.engineio_app.handle_request(environ, start_response)
  File "/usr/local/lib/python3.10/dist-packages/socketio/server.py", line 433, in handle_request
    return self.eio.handle_request(environ, start_response)
  File "/usr/local/lib/python3.10/dist-packages/engineio/server.py", line 272, in handle_request
    socket = self._get_socket(sid)
  File "/usr/local/lib/python3.10/dist-packages/engineio/base_server.py", line 229, in _get_socket
    raise KeyError('Session is disconnected')
KeyError: 'Session is disconnected'
Traceback (most recent call last):
  File "/usr/local/lib/python3.10/dist-packages/flask/app.py", line 1498, in __call__
    return self.wsgi_app(environ, start_response)
  File "/usr/local/lib/python3.10/dist-packages/flask_socketio/__init__.py", line 43, in __call__
    return super(_SocketIOMiddleware, self).__call__(environ,
  File "/usr/local/lib/python3.10/dist-packages/engineio/middleware.py", line 63, in __call__
    return self.engineio_app.handle_request(environ, start_response)
  File "/usr/local/lib/python3.10/dist-packages/socketio/server.py", line 433, in handle_request
    return self.eio.handle_request(environ, start_response)
  File "/usr/local/lib/python3.10/dist-packages/engineio/server.py", line 272, in handle_request
    socket = self._get_socket(sid)
  File "/usr/local/lib/python3.10/dist-packages/engineio/base_server.py", line 229, in _get_socket
    raise KeyError('Session is disconnected')
KeyError: 'Session is disconnected'
Traceback (most recent call last):
  File "/usr/local/lib/python3.10/dist-packages/flask/app.py", line 1498, in __call__
    return self.wsgi_app(environ, start_response)
  File "/usr/local/lib/python3.10/dist-packages/flask_socketio/__init__.py", line 43, in __call__
    return super(_SocketIOMiddleware, self).__call__(environ,
  File "/usr/local/lib/python3.10/dist-packages/engineio/middleware.py", line 63, in __call__
    return self.engineio_app.handle_request(environ, start_response)
  File "/usr/local/lib/python3.10/dist-packages/socketio/server.py", line 433, in handle_request
    return self.eio.handle_request(environ, start_response)
  File "/usr/local/lib/python3.10/dist-packages/engineio/server.py", line 272, in handle_request
    socket = self._get_socket(sid)
  File "/usr/local/lib/python3.10/dist-packages/engineio/base_server.py", line 229, in _get_socket
    raise KeyError('Session is disconnected')
KeyError: 'Session is disconnected'
Traceback (most recent call last):
  File "/usr/local/lib/python3.10/dist-packages/flask/app.py", line 1498, in __call__
    return self.wsgi_app(environ, start_response)
  File "/usr/local/lib/python3.10/dist-packages/flask_socketio/__init__.py", line 43, in __call__
    return super(_SocketIOMiddleware, self).__call__(environ,
  File "/usr/local/lib/python3.10/dist-packages/engineio/middleware.py", line 63, in __call__
    return self.engineio_app.handle_request(environ, start_response)
  File "/usr/local/lib/python3.10/dist-packages/socketio/server.py", line 433, in handle_request
    return self.eio.handle_request(environ, start_response)
  File "/usr/local/lib/python3.10/dist-packages/engineio/server.py", line 272, in handle_request
    socket = self._get_socket(sid)
  File "/usr/local/lib/python3.10/dist-packages/engineio/base_server.py", line 229, in _get_socket
    raise KeyError('Session is disconnected')
KeyError: 'Session is disconnected'
Traceback (most recent call last):
  File "/usr/local/lib/python3.10/dist-packages/flask/app.py", line 1498, in __call__
    return self.wsgi_app(environ, start_response)
  File "/usr/local/lib/python3.10/dist-packages/flask_socketio/__init__.py", line 43, in __call__
    return super(_SocketIOMiddleware, self).__call__(environ,
  File "/usr/local/lib/python3.10/dist-packages/engineio/middleware.py", line 63, in __call__
    return self.engineio_app.handle_request(environ, start_response)
  File "/usr/local/lib/python3.10/dist-packages/socketio/server.py", line 433, in handle_request
    return self.eio.handle_request(environ, start_response)
  File "/usr/local/lib/python3.10/dist-packages/engineio/server.py", line 272, in handle_request
    socket = self._get_socket(sid)
  File "/usr/local/lib/python3.10/dist-packages/engineio/base_server.py", line 229, in _get_socket
    raise KeyError('Session is disconnected')
KeyError: 'Session is disconnected'
Traceback (most recent call last):
  File "/usr/local/lib/python3.10/dist-packages/flask/app.py", line 1498, in __call__
    return self.wsgi_app(environ, start_response)
  File "/usr/local/lib/python3.10/dist-packages/flask_socketio/__init__.py", line 43, in __call__
    return super(_SocketIOMiddleware, self).__call__(environ,
  File "/usr/local/lib/python3.10/dist-packages/engineio/middleware.py", line 63, in __call__
    return self.engineio_app.handle_request(environ, start_response)
  File "/usr/local/lib/python3.10/dist-packages/socketio/server.py", line 433, in handle_request
    return self.eio.handle_request(environ, start_response)
  File "/usr/local/lib/python3.10/dist-packages/engineio/server.py", line 272, in handle_request
    socket = self._get_socket(sid)
  File "/usr/local/lib/python3.10/dist-packages/engineio/base_server.py", line 229, in _get_socket
    raise KeyError('Session is disconnected')
KeyError: 'Session is disconnected'
Traceback (most recent call last):
  File "/usr/local/lib/python3.10/dist-packages/flask/app.py", line 1498, in __call__
    return self.wsgi_app(environ, start_response)
  File "/usr/local/lib/python3.10/dist-packages/flask_socketio/__init__.py", line 43, in __call__
    return super(_SocketIOMiddleware, self).__call__(environ,
  File "/usr/local/lib/python3.10/dist-packages/engineio/middleware.py", line 74, in __call__
    return self.wsgi_app(environ, start_response)
  File "/usr/local/lib/python3.10/dist-packages/flask/app.py", line 1476, in wsgi_app
    response = self.handle_exception(e)
  File "/usr/local/lib/python3.10/dist-packages/flask_cors/extension.py", line 194, in wrapped_function
    return cors_after_request(app.make_response(f(*args, **kwargs)))
  File "/usr/local/lib/python3.10/dist-packages/flask/app.py", line 1473, in wsgi_app
    response = self.full_dispatch_request()
  File "/usr/local/lib/python3.10/dist-packages/flask/app.py", line 882, in full_dispatch_request
    rv = self.handle_user_exception(e)
  File "/usr/local/lib/python3.10/dist-packages/flask_cors/extension.py", line 194, in wrapped_function
    return cors_after_request(app.make_response(f(*args, **kwargs)))
  File "/usr/local/lib/python3.10/dist-packages/flask/app.py", line 880, in full_dispatch_request
    rv = self.dispatch_request()
  File "/usr/local/lib/python3.10/dist-packages/flask/app.py", line 865, in dispatch_request
    return self.ensure_sync(self.view_functions[rule.endpoint])(**view_args)  # type: ignore[no-any-return]
  File "/root/spysnet/website/views.py", line 574, in check_username
    if current_user.type != 'admin':
AttributeError: 'AnonymousUserMixin' object has no attribute 'type'
66.240.192.85 - - [13/Nov/2024 08:34:40] code 400, message Bad request syntax ('SSH-2.0-Go')
5.8.11.202 - - [13/Nov/2024 09:11:00] code 400, message Bad request version ("¯nãY»bhlÿ(=':©\x82ÙoÈ¢×\x93\x98´ï\x80å¹\x90\x00(À")
45.79.128.205 - - [13/Nov/2024 10:43:09] code 400, message Bad request version ('À\x13À')
80.82.77.202 - - [13/Nov/2024 12:03:46] code 400, message Bad request version ("¯nãY»bhlÿ(=':©\x82ÙoÈ¢×\x93\x98´ï\x80å¹\x90\x00(À")
198.235.24.151 - - [13/Nov/2024 13:49:18] code 400, message Bad request version ('À\x13À')
198.235.24.151 - - [13/Nov/2024 13:49:18] code 400, message Bad request syntax ('\x16\x03\x01\x00Ê\x01\x00\x00Æ\x03\x03qß#í\x05')
45.79.128.205 - - [13/Nov/2024 14:02:28] code 400, message Bad request version ('À\x13À')
152.42.214.140 - - [13/Nov/2024 16:03:09] code 400, message Bad request version ('À\x13À')
152.42.243.111 - - [13/Nov/2024 16:03:10] code 400, message Bad request version ('j')
162.142.125.47 - - [13/Nov/2024 19:23:36] code 505, message Invalid HTTP version (2.0)
164.52.24.188 - - [13/Nov/2024 19:26:54] code 400, message Bad request version ("ùÖ¢\x8d\x8ac4Q¼T\x99º\x17:yU.·\x99\x1b\x00>\x13\x02\x13\x03\x13\x01À,À0\x00\x9fÌ©Ì¨ÌªÀ+À/\x00\x9eÀ$À(\x00kÀ#À'\x00gÀ")
216.218.206.66 - - [13/Nov/2024 19:38:34] code 400, message Bad request version ('À\x14À')
172.206.148.199 - - [13/Nov/2024 19:52:51] code 400, message Bad request syntax ('MGLNDD_47.250.51.78_80')
80.82.70.133 - - [13/Nov/2024 20:28:31] code 400, message Bad request version ("¯nãY»bhlÿ(=':©\x82ÙoÈ¢×\x93\x98´ï\x80å¹\x90\x00(À")
Traceback (most recent call last):
  File "/usr/local/lib/python3.10/dist-packages/flask/app.py", line 1498, in __call__
    return self.wsgi_app(environ, start_response)
  File "/usr/local/lib/python3.10/dist-packages/flask_socketio/__init__.py", line 43, in __call__
    return super(_SocketIOMiddleware, self).__call__(environ,
  File "/usr/local/lib/python3.10/dist-packages/engineio/middleware.py", line 74, in __call__
    return self.wsgi_app(environ, start_response)
  File "/usr/local/lib/python3.10/dist-packages/flask/app.py", line 1476, in wsgi_app
    response = self.handle_exception(e)
  File "/usr/local/lib/python3.10/dist-packages/flask_cors/extension.py", line 194, in wrapped_function
    return cors_after_request(app.make_response(f(*args, **kwargs)))
  File "/usr/local/lib/python3.10/dist-packages/flask/app.py", line 1473, in wsgi_app
    response = self.full_dispatch_request()
  File "/usr/local/lib/python3.10/dist-packages/flask/app.py", line 882, in full_dispatch_request
    rv = self.handle_user_exception(e)
  File "/usr/local/lib/python3.10/dist-packages/flask_cors/extension.py", line 194, in wrapped_function
    return cors_after_request(app.make_response(f(*args, **kwargs)))
  File "/usr/local/lib/python3.10/dist-packages/flask/app.py", line 880, in full_dispatch_request
    rv = self.dispatch_request()
  File "/usr/local/lib/python3.10/dist-packages/flask/app.py", line 865, in dispatch_request
    return self.ensure_sync(self.view_functions[rule.endpoint])(**view_args)  # type: ignore[no-any-return]
  File "/root/spysnet/website/views.py", line 574, in check_username
    if current_user.type != 'admin':
AttributeError: 'AnonymousUserMixin' object has no attribute 'type'
Traceback (most recent call last):
  File "/usr/local/lib/python3.10/dist-packages/flask/app.py", line 1498, in __call__
    return self.wsgi_app(environ, start_response)
  File "/usr/local/lib/python3.10/dist-packages/flask_socketio/__init__.py", line 43, in __call__
    return super(_SocketIOMiddleware, self).__call__(environ,
  File "/usr/local/lib/python3.10/dist-packages/engineio/middleware.py", line 74, in __call__
    return self.wsgi_app(environ, start_response)
  File "/usr/local/lib/python3.10/dist-packages/flask/app.py", line 1476, in wsgi_app
    response = self.handle_exception(e)
  File "/usr/local/lib/python3.10/dist-packages/flask_cors/extension.py", line 194, in wrapped_function
    return cors_after_request(app.make_response(f(*args, **kwargs)))
  File "/usr/local/lib/python3.10/dist-packages/flask/app.py", line 1473, in wsgi_app
    response = self.full_dispatch_request()
  File "/usr/local/lib/python3.10/dist-packages/flask/app.py", line 882, in full_dispatch_request
    rv = self.handle_user_exception(e)
  File "/usr/local/lib/python3.10/dist-packages/flask_cors/extension.py", line 194, in wrapped_function
    return cors_after_request(app.make_response(f(*args, **kwargs)))
  File "/usr/local/lib/python3.10/dist-packages/flask/app.py", line 880, in full_dispatch_request
    rv = self.dispatch_request()
  File "/usr/local/lib/python3.10/dist-packages/flask/app.py", line 865, in dispatch_request
    return self.ensure_sync(self.view_functions[rule.endpoint])(**view_args)  # type: ignore[no-any-return]
  File "/root/spysnet/website/views.py", line 574, in check_username
    if current_user.type != 'admin':
AttributeError: 'AnonymousUserMixin' object has no attribute 'type'
Traceback (most recent call last):
  File "/usr/local/lib/python3.10/dist-packages/flask/app.py", line 1498, in __call__
    return self.wsgi_app(environ, start_response)
  File "/usr/local/lib/python3.10/dist-packages/flask_socketio/__init__.py", line 43, in __call__
    return super(_SocketIOMiddleware, self).__call__(environ,
  File "/usr/local/lib/python3.10/dist-packages/engineio/middleware.py", line 63, in __call__
    return self.engineio_app.handle_request(environ, start_response)
  File "/usr/local/lib/python3.10/dist-packages/socketio/server.py", line 433, in handle_request
    return self.eio.handle_request(environ, start_response)
  File "/usr/local/lib/python3.10/dist-packages/engineio/server.py", line 272, in handle_request
    socket = self._get_socket(sid)
  File "/usr/local/lib/python3.10/dist-packages/engineio/base_server.py", line 229, in _get_socket
    raise KeyError('Session is disconnected')
KeyError: 'Session is disconnected'
b'{"success":false,"code":11107,"message":"Couldn\'t verify your request.."}'
b'{"success":false,"code":11107,"message":"Couldn\'t verify your request.."}'
b'{"code":2014,"message":"Domain not allowed"}'
5.101.0.66 - - [13/Nov/2024 23:18:38] code 400, message Bad request version ("¯nãY»bhlÿ(=':©\x82ÙoÈ¢×\x93\x98´ï\x80å¹\x90\x00(À")
b'{"success":false,"code":11103,"message":"Couldn\'t verify your request.."}'
b'{"success":false,"code":11103,"message":"Couldn\'t verify your request.."}'
Traceback (most recent call last):
  File "/usr/local/lib/python3.10/dist-packages/flask/app.py", line 1498, in __call__
    return self.wsgi_app(environ, start_response)
  File "/usr/local/lib/python3.10/dist-packages/flask_socketio/__init__.py", line 43, in __call__
    return super(_SocketIOMiddleware, self).__call__(environ,
  File "/usr/local/lib/python3.10/dist-packages/engineio/middleware.py", line 63, in __call__
    return self.engineio_app.handle_request(environ, start_response)
  File "/usr/local/lib/python3.10/dist-packages/socketio/server.py", line 433, in handle_request
    return self.eio.handle_request(environ, start_response)
  File "/usr/local/lib/python3.10/dist-packages/engineio/server.py", line 272, in handle_request
    socket = self._get_socket(sid)
  File "/usr/local/lib/python3.10/dist-packages/engineio/base_server.py", line 229, in _get_socket
    raise KeyError('Session is disconnected')
KeyError: 'Session is disconnected'
Traceback (most recent call last):
  File "/usr/local/lib/python3.10/dist-packages/flask/app.py", line 1498, in __call__
    return self.wsgi_app(environ, start_response)
  File "/usr/local/lib/python3.10/dist-packages/flask_socketio/__init__.py", line 43, in __call__
    return super(_SocketIOMiddleware, self).__call__(environ,
  File "/usr/local/lib/python3.10/dist-packages/engineio/middleware.py", line 63, in __call__
    return self.engineio_app.handle_request(environ, start_response)
  File "/usr/local/lib/python3.10/dist-packages/socketio/server.py", line 433, in handle_request
    return self.eio.handle_request(environ, start_response)
  File "/usr/local/lib/python3.10/dist-packages/engineio/server.py", line 272, in handle_request
    socket = self._get_socket(sid)
  File "/usr/local/lib/python3.10/dist-packages/engineio/base_server.py", line 229, in _get_socket
    raise KeyError('Session is disconnected')
KeyError: 'Session is disconnected'
Invalid session 4S_-GgBKntEC0QQIAAAT (further occurrences of this error will be logged with level INFO)
Traceback (most recent call last):
  File "/usr/local/lib/python3.10/dist-packages/engineio/async_drivers/_websocket_wsgi.py", line 26, in send
    return self.ws.send(message)
  File "/usr/local/lib/python3.10/dist-packages/simple_websocket/ws.py", line 78, in send
    raise ConnectionClosed(self.close_reason, self.close_message)
simple_websocket.errors.ConnectionClosed: Connection closed: 1005 

During handling of the above exception, another exception occurred:

Traceback (most recent call last):
  File "/usr/local/lib/python3.10/dist-packages/flask/app.py", line 1498, in __call__
    return self.wsgi_app(environ, start_response)
  File "/usr/local/lib/python3.10/dist-packages/flask_socketio/__init__.py", line 43, in __call__
    return super(_SocketIOMiddleware, self).__call__(environ,
  File "/usr/local/lib/python3.10/dist-packages/engineio/middleware.py", line 63, in __call__
    return self.engineio_app.handle_request(environ, start_response)
  File "/usr/local/lib/python3.10/dist-packages/socketio/server.py", line 433, in handle_request
    return self.eio.handle_request(environ, start_response)
  File "/usr/local/lib/python3.10/dist-packages/engineio/server.py", line 274, in handle_request
    packets = socket.handle_get_request(
  File "/usr/local/lib/python3.10/dist-packages/engineio/socket.py", line 90, in handle_get_request
    return getattr(self, '_upgrade_' + transport)(environ,
  File "/usr/local/lib/python3.10/dist-packages/engineio/socket.py", line 146, in _upgrade_websocket
    return ws(environ, start_response)
  File "/usr/local/lib/python3.10/dist-packages/engineio/async_drivers/_websocket_wsgi.py", line 15, in __call__
    ret = self.app(self)
  File "/usr/local/lib/python3.10/dist-packages/engineio/socket.py", line 175, in _websocket_handler
    ws.send(packet.Packet(packet.PONG, data='probe').encode())
  File "/usr/local/lib/python3.10/dist-packages/engineio/async_drivers/_websocket_wsgi.py", line 28, in send
    raise IOError()
OSError
178.128.54.126 - - [14/Nov/2024 00:02:55] code 400, message Bad request version ('ýæI\x8b\x95Æü1\x87Æ£kËÒîK\x16½î·¨ç\x88r)')
152.42.243.111 - - [14/Nov/2024 00:02:56] code 400, message Bad HTTP/0.9 request type ('\x16\x03\x01\x01')
93.174.93.12 - - [14/Nov/2024 00:41:00] code 400, message Bad request version ("¯nãY»bhlÿ(=':©\x82ÙoÈ¢×\x93\x98´ï\x80å¹\x90\x00(À")
167.94.145.97 - - [14/Nov/2024 00:44:31] code 505, message Invalid HTTP version (2.0)
185.81.68.125 - - [14/Nov/2024 01:46:56] code 400, message Bad request version ('À\x13À')
185.81.68.125 - - [14/Nov/2024 01:46:58] code 400, message Bad request version ('À\x13À')
Traceback (most recent call last):
  File "/usr/local/lib/python3.10/dist-packages/flask/app.py", line 1498, in __call__
    return self.wsgi_app(environ, start_response)
  File "/usr/local/lib/python3.10/dist-packages/flask_socketio/__init__.py", line 43, in __call__
    return super(_SocketIOMiddleware, self).__call__(environ,
  File "/usr/local/lib/python3.10/dist-packages/engineio/middleware.py", line 74, in __call__
    return self.wsgi_app(environ, start_response)
  File "/usr/local/lib/python3.10/dist-packages/flask/app.py", line 1476, in wsgi_app
    response = self.handle_exception(e)
  File "/usr/local/lib/python3.10/dist-packages/flask_cors/extension.py", line 194, in wrapped_function
    return cors_after_request(app.make_response(f(*args, **kwargs)))
  File "/usr/local/lib/python3.10/dist-packages/flask/app.py", line 1473, in wsgi_app
    response = self.full_dispatch_request()
  File "/usr/local/lib/python3.10/dist-packages/flask/app.py", line 882, in full_dispatch_request
    rv = self.handle_user_exception(e)
  File "/usr/local/lib/python3.10/dist-packages/flask_cors/extension.py", line 194, in wrapped_function
    return cors_after_request(app.make_response(f(*args, **kwargs)))
  File "/usr/local/lib/python3.10/dist-packages/flask/app.py", line 880, in full_dispatch_request
    rv = self.dispatch_request()
  File "/usr/local/lib/python3.10/dist-packages/flask/app.py", line 865, in dispatch_request
    return self.ensure_sync(self.view_functions[rule.endpoint])(**view_args)  # type: ignore[no-any-return]
  File "/root/spysnet/website/vdo.py", line 946, in ink
    c_keys , mpd = getkeys_ink(token , xotp , ins)
  File "/root/spysnet/website/vdo.py", line 818, in getkeys_ink
    mpd = get_mpd_ink(token , xotp)
  File "/root/spysnet/website/vdo.py", line 794, in get_mpd_ink
    req.raise_for_status()  # Raise an exception if the request fails
  File "/usr/local/lib/python3.10/dist-packages/requests/models.py", line 1024, in raise_for_status
    raise HTTPError(http_error_msg, response=self)
requests.exceptions.HTTPError: 403 Client Error: Forbidden for url: https://api.inkryptvideos.com/api/s1/v_info/d94020bca0824bd8b170233958d05d75
Traceback (most recent call last):
  File "/usr/local/lib/python3.10/dist-packages/flask/app.py", line 1498, in __call__
    return self.wsgi_app(environ, start_response)
  File "/usr/local/lib/python3.10/dist-packages/flask_socketio/__init__.py", line 43, in __call__
    return super(_SocketIOMiddleware, self).__call__(environ,
  File "/usr/local/lib/python3.10/dist-packages/engineio/middleware.py", line 74, in __call__
    return self.wsgi_app(environ, start_response)
  File "/usr/local/lib/python3.10/dist-packages/flask/app.py", line 1476, in wsgi_app
    response = self.handle_exception(e)
  File "/usr/local/lib/python3.10/dist-packages/flask_cors/extension.py", line 194, in wrapped_function
    return cors_after_request(app.make_response(f(*args, **kwargs)))
  File "/usr/local/lib/python3.10/dist-packages/flask/app.py", line 1473, in wsgi_app
    response = self.full_dispatch_request()
  File "/usr/local/lib/python3.10/dist-packages/flask/app.py", line 882, in full_dispatch_request
    rv = self.handle_user_exception(e)
  File "/usr/local/lib/python3.10/dist-packages/flask_cors/extension.py", line 194, in wrapped_function
    return cors_after_request(app.make_response(f(*args, **kwargs)))
  File "/usr/local/lib/python3.10/dist-packages/flask/app.py", line 880, in full_dispatch_request
    rv = self.dispatch_request()
  File "/usr/local/lib/python3.10/dist-packages/flask/app.py", line 865, in dispatch_request
    return self.ensure_sync(self.view_functions[rule.endpoint])(**view_args)  # type: ignore[no-any-return]
  File "/root/spysnet/website/vdo.py", line 946, in ink
    c_keys , mpd = getkeys_ink(token , xotp , ins)
  File "/root/spysnet/website/vdo.py", line 818, in getkeys_ink
    mpd = get_mpd_ink(token , xotp)
  File "/root/spysnet/website/vdo.py", line 794, in get_mpd_ink
    req.raise_for_status()  # Raise an exception if the request fails
  File "/usr/local/lib/python3.10/dist-packages/requests/models.py", line 1024, in raise_for_status
    raise HTTPError(http_error_msg, response=self)
requests.exceptions.HTTPError: 403 Client Error: Forbidden for url: https://api.inkryptvideos.com/api/s1/v_info/d94020bca0824bd8b170233958d05d75
47.237.115.100 - - [14/Nov/2024 05:25:10] code 400, message Bad request version ('À\x14À')
93.174.93.12 - - [14/Nov/2024 05:29:55] code 400, message Bad request version ("¯nãY»bhlÿ(=':©\x82ÙoÈ¢×\x93\x98´ï\x80å¹\x90\x00(À")
45.79.181.104 - - [14/Nov/2024 05:53:21] code 400, message Bad request version ('À\x13À')
5.8.11.202 - - [14/Nov/2024 06:20:55] code 400, message Bad request version ("¯nãY»bhlÿ(=':©\x82ÙoÈ¢×\x93\x98´ï\x80å¹\x90\x00(À")
178.128.54.126 - - [14/Nov/2024 08:02:57] code 400, message Bad HTTP/0.9 request type ('\x16\x03\x01\x01')
152.42.174.244 - - [14/Nov/2024 08:03:03] code 400, message Bad request version ('ð\x00u|\x96\x97¼')
172.104.11.34 - - [14/Nov/2024 08:33:14] code 400, message Bad request version ('À\x13À')
205.210.31.152 - - [14/Nov/2024 09:19:26] code 400, message Bad request version ('À\x13À')
205.210.31.152 - - [14/Nov/2024 09:19:26] code 400, message Bad request version ('À(À$À\x14À')
167.94.138.119 - - [14/Nov/2024 10:42:55] code 505, message Invalid HTTP version (2.0)
b'{"success":false,"code":11107,"message":"Couldn\'t verify your request.."}'
185.147.124.104 - - [14/Nov/2024 12:12:59] code 400, message Bad HTTP/0.9 request type ('\x03\x00\x00/*à\x00\x00\x00\x00\x00Cookie:')
Traceback (most recent call last):
  File "/usr/local/lib/python3.10/dist-packages/flask/app.py", line 1498, in __call__
    return self.wsgi_app(environ, start_response)
  File "/usr/local/lib/python3.10/dist-packages/flask_socketio/__init__.py", line 43, in __call__
    return super(_SocketIOMiddleware, self).__call__(environ,
  File "/usr/local/lib/python3.10/dist-packages/engineio/middleware.py", line 74, in __call__
    return self.wsgi_app(environ, start_response)
  File "/usr/local/lib/python3.10/dist-packages/flask/app.py", line 1476, in wsgi_app
    response = self.handle_exception(e)
  File "/usr/local/lib/python3.10/dist-packages/flask_cors/extension.py", line 194, in wrapped_function
    return cors_after_request(app.make_response(f(*args, **kwargs)))
  File "/usr/local/lib/python3.10/dist-packages/flask/app.py", line 1473, in wsgi_app
    response = self.full_dispatch_request()
  File "/usr/local/lib/python3.10/dist-packages/flask/app.py", line 883, in full_dispatch_request
    return self.finalize_request(rv)
  File "/usr/local/lib/python3.10/dist-packages/flask/app.py", line 902, in finalize_request
    response = self.make_response(rv)
  File "/usr/local/lib/python3.10/dist-packages/flask/app.py", line 1174, in make_response
    raise TypeError(
TypeError: The view function for 'views.check_username' did not return a valid response. The function either returned None or ended without a return statement.
198.235.24.112 - - [14/Nov/2024 12:31:22] code 400, message Bad request version ('À\x13À')
198.235.24.112 - - [14/Nov/2024 12:31:22] code 400, message Bad request version ('À(À$À\x14À')
Traceback (most recent call last):
  File "/usr/local/lib/python3.10/dist-packages/flask/app.py", line 1498, in __call__
    return self.wsgi_app(environ, start_response)
  File "/usr/local/lib/python3.10/dist-packages/flask_socketio/__init__.py", line 43, in __call__
    return super(_SocketIOMiddleware, self).__call__(environ,
  File "/usr/local/lib/python3.10/dist-packages/engineio/middleware.py", line 74, in __call__
    return self.wsgi_app(environ, start_response)
  File "/usr/local/lib/python3.10/dist-packages/flask/app.py", line 1476, in wsgi_app
    response = self.handle_exception(e)
  File "/usr/local/lib/python3.10/dist-packages/flask_cors/extension.py", line 194, in wrapped_function
    return cors_after_request(app.make_response(f(*args, **kwargs)))
  File "/usr/local/lib/python3.10/dist-packages/flask/app.py", line 1473, in wsgi_app
    response = self.full_dispatch_request()
  File "/usr/local/lib/python3.10/dist-packages/flask/app.py", line 883, in full_dispatch_request
    return self.finalize_request(rv)
  File "/usr/local/lib/python3.10/dist-packages/flask/app.py", line 902, in finalize_request
    response = self.make_response(rv)
  File "/usr/local/lib/python3.10/dist-packages/flask/app.py", line 1174, in make_response
    raise TypeError(
TypeError: The view function for 'views.check_username' did not return a valid response. The function either returned None or ended without a return statement.
Traceback (most recent call last):
  File "/usr/local/lib/python3.10/dist-packages/flask/app.py", line 1498, in __call__
    return self.wsgi_app(environ, start_response)
  File "/usr/local/lib/python3.10/dist-packages/flask_socketio/__init__.py", line 43, in __call__
    return super(_SocketIOMiddleware, self).__call__(environ,
  File "/usr/local/lib/python3.10/dist-packages/engineio/middleware.py", line 74, in __call__
    return self.wsgi_app(environ, start_response)
  File "/usr/local/lib/python3.10/dist-packages/flask/app.py", line 1476, in wsgi_app
    response = self.handle_exception(e)
  File "/usr/local/lib/python3.10/dist-packages/flask_cors/extension.py", line 194, in wrapped_function
    return cors_after_request(app.make_response(f(*args, **kwargs)))
  File "/usr/local/lib/python3.10/dist-packages/flask/app.py", line 1473, in wsgi_app
    response = self.full_dispatch_request()
  File "/usr/local/lib/python3.10/dist-packages/flask/app.py", line 883, in full_dispatch_request
    return self.finalize_request(rv)
  File "/usr/local/lib/python3.10/dist-packages/flask/app.py", line 902, in finalize_request
    response = self.make_response(rv)
  File "/usr/local/lib/python3.10/dist-packages/flask/app.py", line 1174, in make_response
    raise TypeError(
TypeError: The view function for 'views.check_username' did not return a valid response. The function either returned None or ended without a return statement.
Traceback (most recent call last):
  File "/usr/local/lib/python3.10/dist-packages/flask/app.py", line 1498, in __call__
    return self.wsgi_app(environ, start_response)
  File "/usr/local/lib/python3.10/dist-packages/flask_socketio/__init__.py", line 43, in __call__
    return super(_SocketIOMiddleware, self).__call__(environ,
  File "/usr/local/lib/python3.10/dist-packages/engineio/middleware.py", line 74, in __call__
    return self.wsgi_app(environ, start_response)
  File "/usr/local/lib/python3.10/dist-packages/flask/app.py", line 1476, in wsgi_app
    response = self.handle_exception(e)
  File "/usr/local/lib/python3.10/dist-packages/flask_cors/extension.py", line 194, in wrapped_function
    return cors_after_request(app.make_response(f(*args, **kwargs)))
  File "/usr/local/lib/python3.10/dist-packages/flask/app.py", line 1473, in wsgi_app
    response = self.full_dispatch_request()
  File "/usr/local/lib/python3.10/dist-packages/flask/app.py", line 883, in full_dispatch_request
    return self.finalize_request(rv)
  File "/usr/local/lib/python3.10/dist-packages/flask/app.py", line 902, in finalize_request
    response = self.make_response(rv)
  File "/usr/local/lib/python3.10/dist-packages/flask/app.py", line 1174, in make_response
    raise TypeError(
TypeError: The view function for 'views.check_username' did not return a valid response. The function either returned None or ended without a return statement.
Traceback (most recent call last):
  File "/usr/local/lib/python3.10/dist-packages/flask/app.py", line 1498, in __call__
    return self.wsgi_app(environ, start_response)
  File "/usr/local/lib/python3.10/dist-packages/flask_socketio/__init__.py", line 43, in __call__
    return super(_SocketIOMiddleware, self).__call__(environ,
  File "/usr/local/lib/python3.10/dist-packages/engineio/middleware.py", line 74, in __call__
    return self.wsgi_app(environ, start_response)
  File "/usr/local/lib/python3.10/dist-packages/flask/app.py", line 1476, in wsgi_app
    response = self.handle_exception(e)
  File "/usr/local/lib/python3.10/dist-packages/flask_cors/extension.py", line 194, in wrapped_function
    return cors_after_request(app.make_response(f(*args, **kwargs)))
  File "/usr/local/lib/python3.10/dist-packages/flask/app.py", line 1473, in wsgi_app
    response = self.full_dispatch_request()
  File "/usr/local/lib/python3.10/dist-packages/flask/app.py", line 883, in full_dispatch_request
    return self.finalize_request(rv)
  File "/usr/local/lib/python3.10/dist-packages/flask/app.py", line 902, in finalize_request
    response = self.make_response(rv)
  File "/usr/local/lib/python3.10/dist-packages/flask/app.py", line 1174, in make_response
    raise TypeError(
TypeError: The view function for 'views.check_username' did not return a valid response. The function either returned None or ended without a return statement.
Traceback (most recent call last):
  File "/usr/local/lib/python3.10/dist-packages/flask/app.py", line 1498, in __call__
    return self.wsgi_app(environ, start_response)
  File "/usr/local/lib/python3.10/dist-packages/flask_socketio/__init__.py", line 43, in __call__
    return super(_SocketIOMiddleware, self).__call__(environ,
  File "/usr/local/lib/python3.10/dist-packages/engineio/middleware.py", line 74, in __call__
    return self.wsgi_app(environ, start_response)
  File "/usr/local/lib/python3.10/dist-packages/flask/app.py", line 1476, in wsgi_app
    response = self.handle_exception(e)
  File "/usr/local/lib/python3.10/dist-packages/flask_cors/extension.py", line 194, in wrapped_function
    return cors_after_request(app.make_response(f(*args, **kwargs)))
  File "/usr/local/lib/python3.10/dist-packages/flask/app.py", line 1473, in wsgi_app
    response = self.full_dispatch_request()
  File "/usr/local/lib/python3.10/dist-packages/flask/app.py", line 883, in full_dispatch_request
    return self.finalize_request(rv)
  File "/usr/local/lib/python3.10/dist-packages/flask/app.py", line 902, in finalize_request
    response = self.make_response(rv)
  File "/usr/local/lib/python3.10/dist-packages/flask/app.py", line 1174, in make_response
    raise TypeError(
TypeError: The view function for 'views.check_username' did not return a valid response. The function either returned None or ended without a return statement.
Traceback (most recent call last):
  File "/usr/local/lib/python3.10/dist-packages/flask/app.py", line 1498, in __call__
    return self.wsgi_app(environ, start_response)
  File "/usr/local/lib/python3.10/dist-packages/flask_socketio/__init__.py", line 43, in __call__
    return super(_SocketIOMiddleware, self).__call__(environ,
  File "/usr/local/lib/python3.10/dist-packages/engineio/middleware.py", line 74, in __call__
    return self.wsgi_app(environ, start_response)
  File "/usr/local/lib/python3.10/dist-packages/flask/app.py", line 1476, in wsgi_app
    response = self.handle_exception(e)
  File "/usr/local/lib/python3.10/dist-packages/flask_cors/extension.py", line 194, in wrapped_function
    return cors_after_request(app.make_response(f(*args, **kwargs)))
  File "/usr/local/lib/python3.10/dist-packages/flask/app.py", line 1473, in wsgi_app
    response = self.full_dispatch_request()
  File "/usr/local/lib/python3.10/dist-packages/flask/app.py", line 883, in full_dispatch_request
    return self.finalize_request(rv)
  File "/usr/local/lib/python3.10/dist-packages/flask/app.py", line 902, in finalize_request
    response = self.make_response(rv)
  File "/usr/local/lib/python3.10/dist-packages/flask/app.py", line 1174, in make_response
    raise TypeError(
TypeError: The view function for 'views.check_username' did not return a valid response. The function either returned None or ended without a return statement.
Traceback (most recent call last):
  File "/usr/local/lib/python3.10/dist-packages/flask/app.py", line 1498, in __call__
    return self.wsgi_app(environ, start_response)
  File "/usr/local/lib/python3.10/dist-packages/flask_socketio/__init__.py", line 43, in __call__
    return super(_SocketIOMiddleware, self).__call__(environ,
  File "/usr/local/lib/python3.10/dist-packages/engineio/middleware.py", line 74, in __call__
    return self.wsgi_app(environ, start_response)
  File "/usr/local/lib/python3.10/dist-packages/flask/app.py", line 1476, in wsgi_app
    response = self.handle_exception(e)
  File "/usr/local/lib/python3.10/dist-packages/flask_cors/extension.py", line 194, in wrapped_function
    return cors_after_request(app.make_response(f(*args, **kwargs)))
  File "/usr/local/lib/python3.10/dist-packages/flask/app.py", line 1473, in wsgi_app
    response = self.full_dispatch_request()
  File "/usr/local/lib/python3.10/dist-packages/flask/app.py", line 883, in full_dispatch_request
    return self.finalize_request(rv)
  File "/usr/local/lib/python3.10/dist-packages/flask/app.py", line 902, in finalize_request
    response = self.make_response(rv)
  File "/usr/local/lib/python3.10/dist-packages/flask/app.py", line 1174, in make_response
    raise TypeError(
TypeError: The view function for 'views.check_username' did not return a valid response. The function either returned None or ended without a return statement.
Traceback (most recent call last):
  File "/usr/local/lib/python3.10/dist-packages/flask/app.py", line 1498, in __call__
    return self.wsgi_app(environ, start_response)
  File "/usr/local/lib/python3.10/dist-packages/flask_socketio/__init__.py", line 43, in __call__
    return super(_SocketIOMiddleware, self).__call__(environ,
  File "/usr/local/lib/python3.10/dist-packages/engineio/middleware.py", line 63, in __call__
    return self.engineio_app.handle_request(environ, start_response)
  File "/usr/local/lib/python3.10/dist-packages/socketio/server.py", line 433, in handle_request
    return self.eio.handle_request(environ, start_response)
  File "/usr/local/lib/python3.10/dist-packages/engineio/server.py", line 272, in handle_request
    socket = self._get_socket(sid)
  File "/usr/local/lib/python3.10/dist-packages/engineio/base_server.py", line 229, in _get_socket
    raise KeyError('Session is disconnected')
KeyError: 'Session is disconnected'
Traceback (most recent call last):
  File "/usr/local/lib/python3.10/dist-packages/flask/app.py", line 1498, in __call__
    return self.wsgi_app(environ, start_response)
  File "/usr/local/lib/python3.10/dist-packages/flask_socketio/__init__.py", line 43, in __call__
    return super(_SocketIOMiddleware, self).__call__(environ,
  File "/usr/local/lib/python3.10/dist-packages/engineio/middleware.py", line 74, in __call__
    return self.wsgi_app(environ, start_response)
  File "/usr/local/lib/python3.10/dist-packages/flask/app.py", line 1476, in wsgi_app
    response = self.handle_exception(e)
  File "/usr/local/lib/python3.10/dist-packages/flask_cors/extension.py", line 194, in wrapped_function
    return cors_after_request(app.make_response(f(*args, **kwargs)))
  File "/usr/local/lib/python3.10/dist-packages/flask/app.py", line 1473, in wsgi_app
    response = self.full_dispatch_request()
  File "/usr/local/lib/python3.10/dist-packages/flask/app.py", line 883, in full_dispatch_request
    return self.finalize_request(rv)
  File "/usr/local/lib/python3.10/dist-packages/flask/app.py", line 902, in finalize_request
    response = self.make_response(rv)
  File "/usr/local/lib/python3.10/dist-packages/flask/app.py", line 1174, in make_response
    raise TypeError(
TypeError: The view function for 'views.check_username' did not return a valid response. The function either returned None or ended without a return statement.
Exception in thread Thread-62 (send_emails):
Traceback (most recent call last):
  File "/usr/lib/python3.10/threading.py", line 1016, in _bootstrap_inner
    self.run()
  File "/usr/lib/python3.10/threading.py", line 953, in run
    self._target(*self._args, **self._kwargs)
TypeError: send_emails() missing 1 required positional argument: 'user_email'
Traceback (most recent call last):
  File "/usr/local/lib/python3.10/dist-packages/flask/app.py", line 1498, in __call__
    return self.wsgi_app(environ, start_response)
  File "/usr/local/lib/python3.10/dist-packages/flask_socketio/__init__.py", line 43, in __call__
    return super(_SocketIOMiddleware, self).__call__(environ,
  File "/usr/local/lib/python3.10/dist-packages/engineio/middleware.py", line 74, in __call__
    return self.wsgi_app(environ, start_response)
  File "/usr/local/lib/python3.10/dist-packages/flask/app.py", line 1476, in wsgi_app
    response = self.handle_exception(e)
  File "/usr/local/lib/python3.10/dist-packages/flask_cors/extension.py", line 194, in wrapped_function
    return cors_after_request(app.make_response(f(*args, **kwargs)))
  File "/usr/local/lib/python3.10/dist-packages/flask/app.py", line 1473, in wsgi_app
    response = self.full_dispatch_request()
  File "/usr/local/lib/python3.10/dist-packages/flask/app.py", line 883, in full_dispatch_request
    return self.finalize_request(rv)
  File "/usr/local/lib/python3.10/dist-packages/flask/app.py", line 902, in finalize_request
    response = self.make_response(rv)
  File "/usr/local/lib/python3.10/dist-packages/flask/app.py", line 1174, in make_response
    raise TypeError(
TypeError: The view function for 'views.check_username' did not return a valid response. The function either returned None or ended without a return statement.
Traceback (most recent call last):
  File "/usr/local/lib/python3.10/dist-packages/flask/app.py", line 1498, in __call__
    return self.wsgi_app(environ, start_response)
  File "/usr/local/lib/python3.10/dist-packages/flask_socketio/__init__.py", line 43, in __call__
    return super(_SocketIOMiddleware, self).__call__(environ,
  File "/usr/local/lib/python3.10/dist-packages/engineio/middleware.py", line 74, in __call__
    return self.wsgi_app(environ, start_response)
  File "/usr/local/lib/python3.10/dist-packages/flask/app.py", line 1476, in wsgi_app
    response = self.handle_exception(e)
  File "/usr/local/lib/python3.10/dist-packages/flask_cors/extension.py", line 194, in wrapped_function
    return cors_after_request(app.make_response(f(*args, **kwargs)))
  File "/usr/local/lib/python3.10/dist-packages/flask/app.py", line 1473, in wsgi_app
    response = self.full_dispatch_request()
  File "/usr/local/lib/python3.10/dist-packages/flask/app.py", line 883, in full_dispatch_request
    return self.finalize_request(rv)
  File "/usr/local/lib/python3.10/dist-packages/flask/app.py", line 902, in finalize_request
    response = self.make_response(rv)
  File "/usr/local/lib/python3.10/dist-packages/flask/app.py", line 1174, in make_response
    raise TypeError(
TypeError: The view function for 'views.check_username' did not return a valid response. The function either returned None or ended without a return statement.
Traceback (most recent call last):
  File "/usr/local/lib/python3.10/dist-packages/flask/app.py", line 1498, in __call__
    return self.wsgi_app(environ, start_response)
  File "/usr/local/lib/python3.10/dist-packages/flask_socketio/__init__.py", line 43, in __call__
    return super(_SocketIOMiddleware, self).__call__(environ,
  File "/usr/local/lib/python3.10/dist-packages/engineio/middleware.py", line 74, in __call__
    return self.wsgi_app(environ, start_response)
  File "/usr/local/lib/python3.10/dist-packages/flask/app.py", line 1476, in wsgi_app
    response = self.handle_exception(e)
  File "/usr/local/lib/python3.10/dist-packages/flask_cors/extension.py", line 194, in wrapped_function
    return cors_after_request(app.make_response(f(*args, **kwargs)))
  File "/usr/local/lib/python3.10/dist-packages/flask/app.py", line 1473, in wsgi_app
    response = self.full_dispatch_request()
  File "/usr/local/lib/python3.10/dist-packages/flask/app.py", line 883, in full_dispatch_request
    return self.finalize_request(rv)
  File "/usr/local/lib/python3.10/dist-packages/flask/app.py", line 902, in finalize_request
    response = self.make_response(rv)
  File "/usr/local/lib/python3.10/dist-packages/flask/app.py", line 1174, in make_response
    raise TypeError(
TypeError: The view function for 'views.check_username' did not return a valid response. The function either returned None or ended without a return statement.
Traceback (most recent call last):
  File "/usr/local/lib/python3.10/dist-packages/flask/app.py", line 1498, in __call__
    return self.wsgi_app(environ, start_response)
  File "/usr/local/lib/python3.10/dist-packages/flask_socketio/__init__.py", line 43, in __call__
    return super(_SocketIOMiddleware, self).__call__(environ,
  File "/usr/local/lib/python3.10/dist-packages/engineio/middleware.py", line 74, in __call__
    return self.wsgi_app(environ, start_response)
  File "/usr/local/lib/python3.10/dist-packages/flask/app.py", line 1476, in wsgi_app
    response = self.handle_exception(e)
  File "/usr/local/lib/python3.10/dist-packages/flask_cors/extension.py", line 194, in wrapped_function
    return cors_after_request(app.make_response(f(*args, **kwargs)))
  File "/usr/local/lib/python3.10/dist-packages/flask/app.py", line 1473, in wsgi_app
    response = self.full_dispatch_request()
  File "/usr/local/lib/python3.10/dist-packages/flask/app.py", line 883, in full_dispatch_request
    return self.finalize_request(rv)
  File "/usr/local/lib/python3.10/dist-packages/flask/app.py", line 902, in finalize_request
    response = self.make_response(rv)
  File "/usr/local/lib/python3.10/dist-packages/flask/app.py", line 1174, in make_response
    raise TypeError(
TypeError: The view function for 'views.check_username' did not return a valid response. The function either returned None or ended without a return statement.
78.153.140.177 - - [14/Nov/2024 12:57:55] code 400, message Bad request syntax ('\x16\x03\x01\x00¬\x01\x00\x00¨\x03\x03\x11li\x99(\x87»<é\x89\x04x$çåõïo\x18r=\x9f\x7f¦®òÎí\x84û\x99¨\x00\x008À,À')
