 * Serving Flask app 'website'
 * Debug mode: on
exiting...
exiting...
exiting...
exiting...
exiting...
exiting...
exiting...
exiting...
exiting...
exiting...
exiting...
exiting...
exiting...
exiting...
exiting...
exiting...
exiting...
exiting...
exiting...
exiting...
exiting...
exiting...
exiting...
exiting...
exiting...
exiting...
exiting...
exiting...
exiting...
exiting...
exiting...
exiting...
exiting...
exiting...
exiting...
exiting...
exiting...
exiting...
exiting...
exiting...
exiting...
exiting...
exiting...
exiting...
exiting...
exiting...
exiting...
exiting...
exiting...
exiting...
exiting...
exiting...
exiting...
exiting...
exiting...
exiting...
exiting...
exiting...
exiting...
exiting...
exiting...
exiting...
exiting...
exiting...
exiting...
exiting...
exiting...
exiting...
exiting...
exiting...
exiting...
exiting...
exiting...
exiting...
exiting...
exiting...
exiting...
exiting...
exiting...
exiting...
exiting...
exiting...
exiting...
exiting...
exiting...
exiting...
exiting...
exiting...
exiting...
exiting...
exiting...
exiting...
exiting...
exiting...
exiting...
exiting...
exiting...
exiting...
exiting...
exiting...
exiting...
exiting...
exiting...
exiting...
exiting...
exiting...
exiting...
exiting...
exiting...
exiting...
exiting...
exiting...
Traceback (most recent call last):
  File "/usr/local/lib/python3.10/dist-packages/flask/app.py", line 1498, in __call__
    return self.wsgi_app(environ, start_response)
  File "/usr/local/lib/python3.10/dist-packages/flask_socketio/__init__.py", line 43, in __call__
    return super(_SocketIOMiddleware, self).__call__(environ,
  File "/usr/local/lib/python3.10/dist-packages/engineio/middleware.py", line 74, in __call__
    return self.wsgi_app(environ, start_response)
  File "/usr/local/lib/python3.10/dist-packages/flask/app.py", line 1476, in wsgi_app
    response = self.handle_exception(e)
  File "/usr/local/lib/python3.10/dist-packages/flask_cors/extension.py", line 194, in wrapped_function
    return cors_after_request(app.make_response(f(*args, **kwargs)))
  File "/usr/local/lib/python3.10/dist-packages/flask/app.py", line 1473, in wsgi_app
    response = self.full_dispatch_request()
  File "/usr/local/lib/python3.10/dist-packages/flask/app.py", line 883, in full_dispatch_request
    return self.finalize_request(rv)
  File "/usr/local/lib/python3.10/dist-packages/flask/app.py", line 902, in finalize_request
    response = self.make_response(rv)
  File "/usr/local/lib/python3.10/dist-packages/flask/app.py", line 1174, in make_response
    raise TypeError(
TypeError: The view function for 'views.check_username' did not return a valid response. The function either returned None or ended without a return statement.
Traceback (most recent call last):
  File "/usr/local/lib/python3.10/dist-packages/flask/app.py", line 1498, in __call__
    return self.wsgi_app(environ, start_response)
  File "/usr/local/lib/python3.10/dist-packages/flask_socketio/__init__.py", line 43, in __call__
    return super(_SocketIOMiddleware, self).__call__(environ,
  File "/usr/local/lib/python3.10/dist-packages/engineio/middleware.py", line 74, in __call__
    return self.wsgi_app(environ, start_response)
  File "/usr/local/lib/python3.10/dist-packages/flask/app.py", line 1476, in wsgi_app
    response = self.handle_exception(e)
  File "/usr/local/lib/python3.10/dist-packages/flask_cors/extension.py", line 194, in wrapped_function
    return cors_after_request(app.make_response(f(*args, **kwargs)))
  File "/usr/local/lib/python3.10/dist-packages/flask/app.py", line 1473, in wsgi_app
    response = self.full_dispatch_request()
  File "/usr/local/lib/python3.10/dist-packages/flask/app.py", line 882, in full_dispatch_request
    rv = self.handle_user_exception(e)
  File "/usr/local/lib/python3.10/dist-packages/flask_cors/extension.py", line 194, in wrapped_function
    return cors_after_request(app.make_response(f(*args, **kwargs)))
  File "/usr/local/lib/python3.10/dist-packages/flask/app.py", line 880, in full_dispatch_request
    rv = self.dispatch_request()
  File "/usr/local/lib/python3.10/dist-packages/flask/app.py", line 865, in dispatch_request
    return self.ensure_sync(self.view_functions[rule.endpoint])(**view_args)  # type: ignore[no-any-return]
  File "/root/spysnet/website/views.py", line 1809, in english_assignment
    discord_log_english(f"{current_user.username} -- Making pdf for {name_and_id} with words {words} ip = {client_ip} <@709799648143081483>")
AttributeError: 'AnonymousUserMixin' object has no attribute 'username'
Traceback (most recent call last):
  File "/usr/local/lib/python3.10/dist-packages/flask/app.py", line 1498, in __call__
    return self.wsgi_app(environ, start_response)
  File "/usr/local/lib/python3.10/dist-packages/flask_socketio/__init__.py", line 43, in __call__
    return super(_SocketIOMiddleware, self).__call__(environ,
  File "/usr/local/lib/python3.10/dist-packages/engineio/middleware.py", line 74, in __call__
    return self.wsgi_app(environ, start_response)
  File "/usr/local/lib/python3.10/dist-packages/flask/app.py", line 1476, in wsgi_app
    response = self.handle_exception(e)
  File "/usr/local/lib/python3.10/dist-packages/flask_cors/extension.py", line 194, in wrapped_function
    return cors_after_request(app.make_response(f(*args, **kwargs)))
  File "/usr/local/lib/python3.10/dist-packages/flask/app.py", line 1473, in wsgi_app
    response = self.full_dispatch_request()
  File "/usr/local/lib/python3.10/dist-packages/flask/app.py", line 883, in full_dispatch_request
    return self.finalize_request(rv)
  File "/usr/local/lib/python3.10/dist-packages/flask/app.py", line 902, in finalize_request
    response = self.make_response(rv)
  File "/usr/local/lib/python3.10/dist-packages/flask/app.py", line 1174, in make_response
    raise TypeError(
TypeError: The view function for 'views.check_username' did not return a valid response. The function either returned None or ended without a return statement.
Traceback (most recent call last):
  File "/usr/local/lib/python3.10/dist-packages/flask/app.py", line 1498, in __call__
    return self.wsgi_app(environ, start_response)
  File "/usr/local/lib/python3.10/dist-packages/flask_socketio/__init__.py", line 43, in __call__
    return super(_SocketIOMiddleware, self).__call__(environ,
  File "/usr/local/lib/python3.10/dist-packages/engineio/middleware.py", line 74, in __call__
    return self.wsgi_app(environ, start_response)
  File "/usr/local/lib/python3.10/dist-packages/flask/app.py", line 1476, in wsgi_app
    response = self.handle_exception(e)
  File "/usr/local/lib/python3.10/dist-packages/flask_cors/extension.py", line 194, in wrapped_function
    return cors_after_request(app.make_response(f(*args, **kwargs)))
  File "/usr/local/lib/python3.10/dist-packages/flask/app.py", line 1473, in wsgi_app
    response = self.full_dispatch_request()
  File "/usr/local/lib/python3.10/dist-packages/flask/app.py", line 883, in full_dispatch_request
    return self.finalize_request(rv)
  File "/usr/local/lib/python3.10/dist-packages/flask/app.py", line 902, in finalize_request
    response = self.make_response(rv)
  File "/usr/local/lib/python3.10/dist-packages/flask/app.py", line 1174, in make_response
    raise TypeError(
TypeError: The view function for 'views.check_username' did not return a valid response. The function either returned None or ended without a return statement.
Traceback (most recent call last):
  File "/usr/local/lib/python3.10/dist-packages/flask/app.py", line 1498, in __call__
    return self.wsgi_app(environ, start_response)
  File "/usr/local/lib/python3.10/dist-packages/flask_socketio/__init__.py", line 43, in __call__
    return super(_SocketIOMiddleware, self).__call__(environ,
  File "/usr/local/lib/python3.10/dist-packages/engineio/middleware.py", line 74, in __call__
    return self.wsgi_app(environ, start_response)
  File "/usr/local/lib/python3.10/dist-packages/flask/app.py", line 1476, in wsgi_app
    response = self.handle_exception(e)
  File "/usr/local/lib/python3.10/dist-packages/flask_cors/extension.py", line 194, in wrapped_function
    return cors_after_request(app.make_response(f(*args, **kwargs)))
  File "/usr/local/lib/python3.10/dist-packages/flask/app.py", line 1473, in wsgi_app
    response = self.full_dispatch_request()
  File "/usr/local/lib/python3.10/dist-packages/flask/app.py", line 882, in full_dispatch_request
    rv = self.handle_user_exception(e)
  File "/usr/local/lib/python3.10/dist-packages/flask_cors/extension.py", line 194, in wrapped_function
    return cors_after_request(app.make_response(f(*args, **kwargs)))
  File "/usr/local/lib/python3.10/dist-packages/flask/app.py", line 880, in full_dispatch_request
    rv = self.dispatch_request()
  File "/usr/local/lib/python3.10/dist-packages/flask/app.py", line 865, in dispatch_request
    return self.ensure_sync(self.view_functions[rule.endpoint])(**view_args)  # type: ignore[no-any-return]
  File "/root/spysnet/website/views.py", line 2218, in english_assignment
    fields_data =  update_fields_data(fields_data_low, data)
  File "/root/spysnet/website/views.py", line 2078, in update_fields_data
    fields_data[f"Today's POWER WORD {i}"]["text"] = word_data["Today's POWER WORD"]
KeyError: "Today's POWER WORD"
Traceback (most recent call last):
  File "/usr/local/lib/python3.10/dist-packages/flask/app.py", line 1498, in __call__
    return self.wsgi_app(environ, start_response)
  File "/usr/local/lib/python3.10/dist-packages/flask_socketio/__init__.py", line 43, in __call__
    return super(_SocketIOMiddleware, self).__call__(environ,
  File "/usr/local/lib/python3.10/dist-packages/engineio/middleware.py", line 74, in __call__
    return self.wsgi_app(environ, start_response)
  File "/usr/local/lib/python3.10/dist-packages/flask/app.py", line 1476, in wsgi_app
    response = self.handle_exception(e)
  File "/usr/local/lib/python3.10/dist-packages/flask_cors/extension.py", line 194, in wrapped_function
    return cors_after_request(app.make_response(f(*args, **kwargs)))
  File "/usr/local/lib/python3.10/dist-packages/flask/app.py", line 1473, in wsgi_app
    response = self.full_dispatch_request()
  File "/usr/local/lib/python3.10/dist-packages/flask/app.py", line 883, in full_dispatch_request
    return self.finalize_request(rv)
  File "/usr/local/lib/python3.10/dist-packages/flask/app.py", line 902, in finalize_request
    response = self.make_response(rv)
  File "/usr/local/lib/python3.10/dist-packages/flask/app.py", line 1174, in make_response
    raise TypeError(
TypeError: The view function for 'views.check_username' did not return a valid response. The function either returned None or ended without a return statement.
Invalid session BjazB68zf4GGRRlvAAAF (further occurrences of this error will be logged with level INFO)
Traceback (most recent call last):
  File "/usr/local/lib/python3.10/dist-packages/flask/app.py", line 1498, in __call__
    return self.wsgi_app(environ, start_response)
  File "/usr/local/lib/python3.10/dist-packages/flask_socketio/__init__.py", line 43, in __call__
    return super(_SocketIOMiddleware, self).__call__(environ,
  File "/usr/local/lib/python3.10/dist-packages/engineio/middleware.py", line 74, in __call__
    return self.wsgi_app(environ, start_response)
  File "/usr/local/lib/python3.10/dist-packages/flask/app.py", line 1476, in wsgi_app
    response = self.handle_exception(e)
  File "/usr/local/lib/python3.10/dist-packages/flask_cors/extension.py", line 194, in wrapped_function
    return cors_after_request(app.make_response(f(*args, **kwargs)))
  File "/usr/local/lib/python3.10/dist-packages/flask/app.py", line 1473, in wsgi_app
    response = self.full_dispatch_request()
  File "/usr/local/lib/python3.10/dist-packages/flask/app.py", line 883, in full_dispatch_request
    return self.finalize_request(rv)
  File "/usr/local/lib/python3.10/dist-packages/flask/app.py", line 902, in finalize_request
    response = self.make_response(rv)
  File "/usr/local/lib/python3.10/dist-packages/flask/app.py", line 1174, in make_response
    raise TypeError(
TypeError: The view function for 'views.check_username' did not return a valid response. The function either returned None or ended without a return statement.
Traceback (most recent call last):
  File "/usr/local/lib/python3.10/dist-packages/flask/app.py", line 1498, in __call__
    return self.wsgi_app(environ, start_response)
  File "/usr/local/lib/python3.10/dist-packages/flask_socketio/__init__.py", line 43, in __call__
    return super(_SocketIOMiddleware, self).__call__(environ,
  File "/usr/local/lib/python3.10/dist-packages/engineio/middleware.py", line 74, in __call__
    return self.wsgi_app(environ, start_response)
  File "/usr/local/lib/python3.10/dist-packages/flask/app.py", line 1476, in wsgi_app
    response = self.handle_exception(e)
  File "/usr/local/lib/python3.10/dist-packages/flask_cors/extension.py", line 194, in wrapped_function
    return cors_after_request(app.make_response(f(*args, **kwargs)))
  File "/usr/local/lib/python3.10/dist-packages/flask/app.py", line 1473, in wsgi_app
    response = self.full_dispatch_request()
  File "/usr/local/lib/python3.10/dist-packages/flask/app.py", line 882, in full_dispatch_request
    rv = self.handle_user_exception(e)
  File "/usr/local/lib/python3.10/dist-packages/flask_cors/extension.py", line 194, in wrapped_function
    return cors_after_request(app.make_response(f(*args, **kwargs)))
  File "/usr/local/lib/python3.10/dist-packages/flask/app.py", line 880, in full_dispatch_request
    rv = self.dispatch_request()
  File "/usr/local/lib/python3.10/dist-packages/flask/app.py", line 865, in dispatch_request
    return self.ensure_sync(self.view_functions[rule.endpoint])(**view_args)  # type: ignore[no-any-return]
  File "/root/spysnet/website/views.py", line 2217, in english_assignment
    make_image_final('high' , 300 , 100 ,img_1_cords , img_2_cords )
  File "/root/spysnet/website/views.py", line 2208, in make_image_final
    if image.mode in ("RGBA", "P"):
UnboundLocalError: local variable 'image' referenced before assignment
Traceback (most recent call last):
  File "/usr/local/lib/python3.10/dist-packages/flask/app.py", line 1498, in __call__
    return self.wsgi_app(environ, start_response)
  File "/usr/local/lib/python3.10/dist-packages/flask_socketio/__init__.py", line 43, in __call__
    return super(_SocketIOMiddleware, self).__call__(environ,
  File "/usr/local/lib/python3.10/dist-packages/engineio/middleware.py", line 63, in __call__
    return self.engineio_app.handle_request(environ, start_response)
  File "/usr/local/lib/python3.10/dist-packages/socketio/server.py", line 433, in handle_request
    return self.eio.handle_request(environ, start_response)
  File "/usr/local/lib/python3.10/dist-packages/engineio/server.py", line 272, in handle_request
    socket = self._get_socket(sid)
  File "/usr/local/lib/python3.10/dist-packages/engineio/base_server.py", line 229, in _get_socket
    raise KeyError('Session is disconnected')
KeyError: 'Session is disconnected'
Traceback (most recent call last):
  File "/usr/local/lib/python3.10/dist-packages/flask/app.py", line 1498, in __call__
    return self.wsgi_app(environ, start_response)
  File "/usr/local/lib/python3.10/dist-packages/flask_socketio/__init__.py", line 43, in __call__
    return super(_SocketIOMiddleware, self).__call__(environ,
  File "/usr/local/lib/python3.10/dist-packages/engineio/middleware.py", line 74, in __call__
    return self.wsgi_app(environ, start_response)
  File "/usr/local/lib/python3.10/dist-packages/flask/app.py", line 1476, in wsgi_app
    response = self.handle_exception(e)
  File "/usr/local/lib/python3.10/dist-packages/flask_cors/extension.py", line 194, in wrapped_function
    return cors_after_request(app.make_response(f(*args, **kwargs)))
  File "/usr/local/lib/python3.10/dist-packages/flask/app.py", line 1473, in wsgi_app
    response = self.full_dispatch_request()
  File "/usr/local/lib/python3.10/dist-packages/flask/app.py", line 882, in full_dispatch_request
    rv = self.handle_user_exception(e)
  File "/usr/local/lib/python3.10/dist-packages/flask_cors/extension.py", line 194, in wrapped_function
    return cors_after_request(app.make_response(f(*args, **kwargs)))
  File "/usr/local/lib/python3.10/dist-packages/flask/app.py", line 880, in full_dispatch_request
    rv = self.dispatch_request()
  File "/usr/local/lib/python3.10/dist-packages/flask/app.py", line 865, in dispatch_request
    return self.ensure_sync(self.view_functions[rule.endpoint])(**view_args)  # type: ignore[no-any-return]
  File "/root/spysnet/website/views.py", line 2260, in english_assignment
    make_image_final('low' , 30 , 10 ,img_1_cords,img_2_cords )
  File "/root/spysnet/website/views.py", line 2238, in make_image_final
    add_image(main_image, "./website/english/img2.png", img_2_cords)
  File "/root/spysnet/website/views.py", line 2220, in add_image
    added_image = Image.open(added_image_path)
  File "/usr/local/lib/python3.10/dist-packages/PIL/Image.py", line 3536, in open
    raise UnidentifiedImageError(msg)
PIL.UnidentifiedImageError: cannot identify image file '/root/spysnet/website/english/img2.png'
Traceback (most recent call last):
  File "/usr/local/lib/python3.10/dist-packages/flask/app.py", line 1498, in __call__
    return self.wsgi_app(environ, start_response)
  File "/usr/local/lib/python3.10/dist-packages/flask_socketio/__init__.py", line 43, in __call__
    return super(_SocketIOMiddleware, self).__call__(environ,
  File "/usr/local/lib/python3.10/dist-packages/engineio/middleware.py", line 74, in __call__
    return self.wsgi_app(environ, start_response)
  File "/usr/local/lib/python3.10/dist-packages/flask/app.py", line 1476, in wsgi_app
    response = self.handle_exception(e)
  File "/usr/local/lib/python3.10/dist-packages/flask_cors/extension.py", line 194, in wrapped_function
    return cors_after_request(app.make_response(f(*args, **kwargs)))
  File "/usr/local/lib/python3.10/dist-packages/flask/app.py", line 1473, in wsgi_app
    response = self.full_dispatch_request()
  File "/usr/local/lib/python3.10/dist-packages/flask/app.py", line 883, in full_dispatch_request
    return self.finalize_request(rv)
  File "/usr/local/lib/python3.10/dist-packages/flask/app.py", line 902, in finalize_request
    response = self.make_response(rv)
  File "/usr/local/lib/python3.10/dist-packages/flask/app.py", line 1174, in make_response
    raise TypeError(
TypeError: The view function for 'views.check_username' did not return a valid response. The function either returned None or ended without a return statement.
Traceback (most recent call last):
  File "/usr/local/lib/python3.10/dist-packages/flask/app.py", line 1498, in __call__
    return self.wsgi_app(environ, start_response)
  File "/usr/local/lib/python3.10/dist-packages/flask_socketio/__init__.py", line 43, in __call__
    return super(_SocketIOMiddleware, self).__call__(environ,
  File "/usr/local/lib/python3.10/dist-packages/engineio/middleware.py", line 74, in __call__
    return self.wsgi_app(environ, start_response)
  File "/usr/local/lib/python3.10/dist-packages/flask/app.py", line 1476, in wsgi_app
    response = self.handle_exception(e)
  File "/usr/local/lib/python3.10/dist-packages/flask_cors/extension.py", line 194, in wrapped_function
    return cors_after_request(app.make_response(f(*args, **kwargs)))
  File "/usr/local/lib/python3.10/dist-packages/flask/app.py", line 1473, in wsgi_app
    response = self.full_dispatch_request()
  File "/usr/local/lib/python3.10/dist-packages/flask/app.py", line 883, in full_dispatch_request
    return self.finalize_request(rv)
  File "/usr/local/lib/python3.10/dist-packages/flask/app.py", line 902, in finalize_request
    response = self.make_response(rv)
  File "/usr/local/lib/python3.10/dist-packages/flask/app.py", line 1174, in make_response
    raise TypeError(
TypeError: The view function for 'views.check_username' did not return a valid response. The function either returned None or ended without a return statement.
Traceback (most recent call last):
  File "/usr/local/lib/python3.10/dist-packages/flask/app.py", line 1498, in __call__
    return self.wsgi_app(environ, start_response)
  File "/usr/local/lib/python3.10/dist-packages/flask_socketio/__init__.py", line 43, in __call__
    return super(_SocketIOMiddleware, self).__call__(environ,
  File "/usr/local/lib/python3.10/dist-packages/engineio/middleware.py", line 74, in __call__
    return self.wsgi_app(environ, start_response)
  File "/usr/local/lib/python3.10/dist-packages/flask/app.py", line 1476, in wsgi_app
    response = self.handle_exception(e)
  File "/usr/local/lib/python3.10/dist-packages/flask_cors/extension.py", line 194, in wrapped_function
    return cors_after_request(app.make_response(f(*args, **kwargs)))
  File "/usr/local/lib/python3.10/dist-packages/flask/app.py", line 1473, in wsgi_app
    response = self.full_dispatch_request()
  File "/usr/local/lib/python3.10/dist-packages/flask/app.py", line 882, in full_dispatch_request
    rv = self.handle_user_exception(e)
  File "/usr/local/lib/python3.10/dist-packages/flask_cors/extension.py", line 194, in wrapped_function
    return cors_after_request(app.make_response(f(*args, **kwargs)))
  File "/usr/local/lib/python3.10/dist-packages/flask/app.py", line 880, in full_dispatch_request
    rv = self.dispatch_request()
  File "/usr/local/lib/python3.10/dist-packages/flask/app.py", line 865, in dispatch_request
    return self.ensure_sync(self.view_functions[rule.endpoint])(**view_args)  # type: ignore[no-any-return]
  File "/root/spysnet/website/views.py", line 1811, in english_assignment
    discord_log_english(f"Not logged -- Making pdf for {name_and_id} with words {words} api = {api} , quality = {quality} , ip = {client_ip} <@709799648143081483>")
UnboundLocalError: local variable 'client_ip' referenced before assignment
Traceback (most recent call last):
  File "/usr/local/lib/python3.10/dist-packages/flask/app.py", line 1498, in __call__
    return self.wsgi_app(environ, start_response)
  File "/usr/local/lib/python3.10/dist-packages/flask_socketio/__init__.py", line 43, in __call__
    return super(_SocketIOMiddleware, self).__call__(environ,
  File "/usr/local/lib/python3.10/dist-packages/engineio/middleware.py", line 74, in __call__
    return self.wsgi_app(environ, start_response)
  File "/usr/local/lib/python3.10/dist-packages/flask/app.py", line 1476, in wsgi_app
    response = self.handle_exception(e)
  File "/usr/local/lib/python3.10/dist-packages/flask_cors/extension.py", line 194, in wrapped_function
    return cors_after_request(app.make_response(f(*args, **kwargs)))
  File "/usr/local/lib/python3.10/dist-packages/flask/app.py", line 1473, in wsgi_app
    response = self.full_dispatch_request()
  File "/usr/local/lib/python3.10/dist-packages/flask/app.py", line 882, in full_dispatch_request
    rv = self.handle_user_exception(e)
  File "/usr/local/lib/python3.10/dist-packages/flask_cors/extension.py", line 194, in wrapped_function
    return cors_after_request(app.make_response(f(*args, **kwargs)))
  File "/usr/local/lib/python3.10/dist-packages/flask/app.py", line 880, in full_dispatch_request
    rv = self.dispatch_request()
  File "/usr/local/lib/python3.10/dist-packages/flask/app.py", line 865, in dispatch_request
    return self.ensure_sync(self.view_functions[rule.endpoint])(**view_args)  # type: ignore[no-any-return]
  File "/root/spysnet/website/views.py", line 1811, in english_assignment
    discord_log_english(f"Not logged -- Making pdf for {name_and_id} with words {words} api = {api} , quality = {quality} , ip = {client_ip} <@709799648143081483>")
UnboundLocalError: local variable 'client_ip' referenced before assignment
Invalid session uvUgfxM0zPRolFfvAAAM (further occurrences of this error will be logged with level INFO)
152.42.243.111 - - [21/Nov/2024 16:03:08] code 400, message Bad request version ('À\x13À')
152.42.243.206 - - [21/Nov/2024 16:03:09] code 400, message Bad request version ('À\x13À')
80.82.78.39 - - [21/Nov/2024 17:17:48] code 400, message Bad request version ('À\x13À')
80.82.77.202 - - [21/Nov/2024 18:31:50] code 400, message Bad request version ("¯nãY»bhlÿ(=':©\x82ÙoÈ¢×\x93\x98´ï\x80å¹\x90\x00(À")
65.49.1.107 - - [21/Nov/2024 19:07:39] code 400, message Bad HTTP/0.9 request type ('\x16\x03\x01\x00{\x01\x00\x00w\x03\x03³Îx\x06¹UW\x988ÊR\x10$%_zníêç¿\x07æm\x84{dÒ\x99\x02¼$\x00\x00\x1aÀ/À+À\x11À\x07À\x13À')
93.174.93.12 - - [21/Nov/2024 20:35:53] code 400, message Bad request version ("¯nãY»bhlÿ(=':©\x82ÙoÈ¢×\x93\x98´ï\x80å¹\x90\x00(À")
185.85.239.13 - - [21/Nov/2024 21:56:46] code 400, message Bad request version ("\x02\x15\x86iÐ¤ÁîõG³úr\x82&Ð»\x17Õ\x00È\x13\x01\x13\x02\x13\x03\x13\x04\x13\x05À,À0\x00£\x00\x9fÌ©Ì¨ÌªÀ¯À\xadÀ£À\x9fÀ]ÀaÀWÀS\x00§À+À/\x00¢\x00\x9eÀ®À¬À¢À\x9eÀ\\À`ÀVÀR\x00¦À$À(\x00k\x00jÀsÀw\x00Ä\x00Ã\x00m\x00ÅÀ#À'\x00g\x00@ÀrÀv\x00¾\x00½\x00l\x00¿À")
185.85.239.13 - - [21/Nov/2024 22:24:51] code 400, message Bad request version ('DªîWÞ}ì\x9b¾\x01\x98(\x18b)/üh¢\x86\x02ò\x8d©5ð\x16\x81"mkÍ\x00È\x13\x01\x13\x02\x13\x03\x13\x04\x13\x05À,À0\x00£\x00\x9fÌ©Ì¨ÌªÀ¯À\xadÀ£À\x9fÀ]ÀaÀWÀS\x00§À+À/\x00¢\x00\x9eÀ®À¬À¢À\x9eÀ\\À`ÀVÀR\x00¦À$À(\x00k\x00jÀsÀw\x00Ä\x00Ã\x00m\x00ÅÀ#À\'\x00g\x00@ÀrÀv\x00¾\x00½\x00l\x00¿À')
185.85.239.13 - - [21/Nov/2024 22:53:01] code 400, message Bad request version ('VÃaµ\x0f´Ë')
185.85.239.13 - - [21/Nov/2024 23:26:12] code 400, message Bad HTTP/0.9 request type ('\x16\x03\x01\x01ª\x01\x00\x01¦\x03\x03ç¨Â?ó\x89w\x93s\x89µÅ¸[¾@ÛËòÜÁbwµùÐ\x83®f\x05u0')
206.189.98.12 - - [21/Nov/2024 23:35:12] code 400, message Bad HTTP/0.9 request type ("\x16\x03\x01\x00{\x01\x00\x00w\x03\x03'Mì¼\x9fÝ?\x95\x01\x8c\x97z7¦:£»)¦\x9dî$w\x95x\x02ç\x19ddÜÂ\x00\x00\x1aÀ/À+À\x11À\x07À\x13À")
206.189.98.12 - - [21/Nov/2024 23:35:12] code 400, message Bad request version ('À\x14À')
152.42.243.111 - - [22/Nov/2024 00:03:07] code 400, message Bad request version ('À\x13À')
159.223.67.34 - - [22/Nov/2024 00:03:09] code 400, message Bad request version ('À\x13À')
52.234.238.239 - - [22/Nov/2024 01:30:23] code 400, message Bad request syntax ('MGLNDD_47.250.51.78_80')
167.94.145.97 - - [22/Nov/2024 02:22:10] code 505, message Invalid HTTP version (2.0)
80.82.78.39 - - [22/Nov/2024 02:33:45] code 400, message Bad request version ('°wG\x9f')
159.89.27.86 - - [22/Nov/2024 03:03:35] code 400, message Bad request version ('À\x14À')
159.89.27.86 - - [22/Nov/2024 03:03:36] code 400, message Bad request version ('À\x14À')
162.142.125.33 - - [22/Nov/2024 03:51:37] code 505, message Invalid HTTP version (2.0)
