 * Serving Flask app 'website'
 * Debug mode: on
Traceback (most recent call last):
  File "/usr/local/lib/python3.10/dist-packages/flask/app.py", line 1498, in __call__
    return self.wsgi_app(environ, start_response)
  File "/usr/local/lib/python3.10/dist-packages/flask_socketio/__init__.py", line 43, in __call__
    return super(_SocketIOMiddleware, self).__call__(environ,
  File "/usr/local/lib/python3.10/dist-packages/engineio/middleware.py", line 74, in __call__
    return self.wsgi_app(environ, start_response)
  File "/usr/local/lib/python3.10/dist-packages/flask/app.py", line 1476, in wsgi_app
    response = self.handle_exception(e)
  File "/usr/local/lib/python3.10/dist-packages/flask_cors/extension.py", line 194, in wrapped_function
    return cors_after_request(app.make_response(f(*args, **kwargs)))
  File "/usr/local/lib/python3.10/dist-packages/flask/app.py", line 1473, in wsgi_app
    response = self.full_dispatch_request()
  File "/usr/local/lib/python3.10/dist-packages/flask/app.py", line 882, in full_dispatch_request
    rv = self.handle_user_exception(e)
  File "/usr/local/lib/python3.10/dist-packages/flask_cors/extension.py", line 194, in wrapped_function
    return cors_after_request(app.make_response(f(*args, **kwargs)))
  File "/usr/local/lib/python3.10/dist-packages/flask/app.py", line 880, in full_dispatch_request
    rv = self.dispatch_request()
  File "/usr/local/lib/python3.10/dist-packages/flask/app.py", line 865, in dispatch_request
    return self.ensure_sync(self.view_functions[rule.endpoint])(**view_args)  # type: ignore[no-any-return]
  File "/root/spysnet/website/views.py", line 1064, in manage_user
    'subscription_method': user.subscription_method,
AttributeError: 'User' object has no attribute 'subscription_method'
Invalid session TjPaejDi_cWhGXZlAAAE (further occurrences of this error will be logged with level INFO)
Traceback (most recent call last):
  File "/usr/local/lib/python3.10/dist-packages/flask/app.py", line 1498, in __call__
    return self.wsgi_app(environ, start_response)
  File "/usr/local/lib/python3.10/dist-packages/flask_socketio/__init__.py", line 43, in __call__
    return super(_SocketIOMiddleware, self).__call__(environ,
  File "/usr/local/lib/python3.10/dist-packages/engineio/middleware.py", line 74, in __call__
    return self.wsgi_app(environ, start_response)
  File "/usr/local/lib/python3.10/dist-packages/flask/app.py", line 1476, in wsgi_app
    response = self.handle_exception(e)
  File "/usr/local/lib/python3.10/dist-packages/flask_cors/extension.py", line 194, in wrapped_function
    return cors_after_request(app.make_response(f(*args, **kwargs)))
  File "/usr/local/lib/python3.10/dist-packages/flask/app.py", line 1473, in wsgi_app
    response = self.full_dispatch_request()
  File "/usr/local/lib/python3.10/dist-packages/flask/app.py", line 882, in full_dispatch_request
    rv = self.handle_user_exception(e)
  File "/usr/local/lib/python3.10/dist-packages/flask_cors/extension.py", line 194, in wrapped_function
    return cors_after_request(app.make_response(f(*args, **kwargs)))
  File "/usr/local/lib/python3.10/dist-packages/flask/app.py", line 880, in full_dispatch_request
    rv = self.dispatch_request()
  File "/usr/local/lib/python3.10/dist-packages/flask/app.py", line 865, in dispatch_request
    return self.ensure_sync(self.view_functions[rule.endpoint])(**view_args)  # type: ignore[no-any-return]
  File "/root/spysnet/website/views.py", line 589, in subjectspage
    end_date = current_user.subscription_date + timedelta(days=30)
AttributeError: 'User' object has no attribute 'subscription_date'
Traceback (most recent call last):
  File "/usr/local/lib/python3.10/dist-packages/flask/app.py", line 1498, in __call__
    return self.wsgi_app(environ, start_response)
  File "/usr/local/lib/python3.10/dist-packages/flask_socketio/__init__.py", line 43, in __call__
    return super(_SocketIOMiddleware, self).__call__(environ,
  File "/usr/local/lib/python3.10/dist-packages/engineio/middleware.py", line 63, in __call__
    return self.engineio_app.handle_request(environ, start_response)
  File "/usr/local/lib/python3.10/dist-packages/socketio/server.py", line 433, in handle_request
    return self.eio.handle_request(environ, start_response)
  File "/usr/local/lib/python3.10/dist-packages/engineio/server.py", line 272, in handle_request
    socket = self._get_socket(sid)
  File "/usr/local/lib/python3.10/dist-packages/engineio/base_server.py", line 229, in _get_socket
    raise KeyError('Session is disconnected')
KeyError: 'Session is disconnected'
Traceback (most recent call last):
  File "/usr/local/lib/python3.10/dist-packages/flask/app.py", line 1498, in __call__
    return self.wsgi_app(environ, start_response)
  File "/usr/local/lib/python3.10/dist-packages/flask_socketio/__init__.py", line 43, in __call__
    return super(_SocketIOMiddleware, self).__call__(environ,
  File "/usr/local/lib/python3.10/dist-packages/engineio/middleware.py", line 74, in __call__
    return self.wsgi_app(environ, start_response)
  File "/usr/local/lib/python3.10/dist-packages/flask/app.py", line 1476, in wsgi_app
    response = self.handle_exception(e)
  File "/usr/local/lib/python3.10/dist-packages/flask_cors/extension.py", line 194, in wrapped_function
    return cors_after_request(app.make_response(f(*args, **kwargs)))
  File "/usr/local/lib/python3.10/dist-packages/flask/app.py", line 1473, in wsgi_app
    response = self.full_dispatch_request()
  File "/usr/local/lib/python3.10/dist-packages/flask/app.py", line 883, in full_dispatch_request
    return self.finalize_request(rv)
  File "/usr/local/lib/python3.10/dist-packages/flask/app.py", line 902, in finalize_request
    response = self.make_response(rv)
  File "/usr/local/lib/python3.10/dist-packages/flask/app.py", line 1211, in make_response
    raise TypeError(
TypeError: The view function did not return a valid response. The return type must be a string, dict, list, tuple with headers or status, Response instance, or WSGI callable, but it was a int.
Invalid session RbfX-JDXCNnXJg2QAAAF (further occurrences of this error will be logged with level INFO)
Traceback (most recent call last):
  File "/usr/local/lib/python3.10/dist-packages/flask/app.py", line 1498, in __call__
    return self.wsgi_app(environ, start_response)
  File "/usr/local/lib/python3.10/dist-packages/flask_socketio/__init__.py", line 43, in __call__
    return super(_SocketIOMiddleware, self).__call__(environ,
  File "/usr/local/lib/python3.10/dist-packages/engineio/middleware.py", line 74, in __call__
    return self.wsgi_app(environ, start_response)
  File "/usr/local/lib/python3.10/dist-packages/flask/app.py", line 1476, in wsgi_app
    response = self.handle_exception(e)
  File "/usr/local/lib/python3.10/dist-packages/flask_cors/extension.py", line 194, in wrapped_function
    return cors_after_request(app.make_response(f(*args, **kwargs)))
  File "/usr/local/lib/python3.10/dist-packages/flask/app.py", line 1473, in wsgi_app
    response = self.full_dispatch_request()
  File "/usr/local/lib/python3.10/dist-packages/flask/app.py", line 882, in full_dispatch_request
    rv = self.handle_user_exception(e)
  File "/usr/local/lib/python3.10/dist-packages/flask_cors/extension.py", line 194, in wrapped_function
    return cors_after_request(app.make_response(f(*args, **kwargs)))
  File "/usr/local/lib/python3.10/dist-packages/flask/app.py", line 880, in full_dispatch_request
    rv = self.dispatch_request()
  File "/usr/local/lib/python3.10/dist-packages/flask/app.py", line 865, in dispatch_request
    return self.ensure_sync(self.view_functions[rule.endpoint])(**view_args)  # type: ignore[no-any-return]
  File "/root/spysnet/website/views.py", line 563, in check_username
    if current_user.type != 'admin':
AttributeError: 'AnonymousUserMixin' object has no attribute 'type'
Traceback (most recent call last):
  File "/usr/local/lib/python3.10/dist-packages/flask/app.py", line 1498, in __call__
    return self.wsgi_app(environ, start_response)
  File "/usr/local/lib/python3.10/dist-packages/flask_socketio/__init__.py", line 43, in __call__
    return super(_SocketIOMiddleware, self).__call__(environ,
  File "/usr/local/lib/python3.10/dist-packages/engineio/middleware.py", line 63, in __call__
    return self.engineio_app.handle_request(environ, start_response)
  File "/usr/local/lib/python3.10/dist-packages/socketio/server.py", line 433, in handle_request
    return self.eio.handle_request(environ, start_response)
  File "/usr/local/lib/python3.10/dist-packages/engineio/server.py", line 272, in handle_request
    socket = self._get_socket(sid)
  File "/usr/local/lib/python3.10/dist-packages/engineio/base_server.py", line 229, in _get_socket
    raise KeyError('Session is disconnected')
KeyError: 'Session is disconnected'
Traceback (most recent call last):
  File "/usr/local/lib/python3.10/dist-packages/flask/app.py", line 1498, in __call__
    return self.wsgi_app(environ, start_response)
  File "/usr/local/lib/python3.10/dist-packages/flask_socketio/__init__.py", line 43, in __call__
    return super(_SocketIOMiddleware, self).__call__(environ,
  File "/usr/local/lib/python3.10/dist-packages/engineio/middleware.py", line 74, in __call__
    return self.wsgi_app(environ, start_response)
  File "/usr/local/lib/python3.10/dist-packages/flask/app.py", line 1476, in wsgi_app
    response = self.handle_exception(e)
  File "/usr/local/lib/python3.10/dist-packages/flask_cors/extension.py", line 194, in wrapped_function
    return cors_after_request(app.make_response(f(*args, **kwargs)))
  File "/usr/local/lib/python3.10/dist-packages/flask/app.py", line 1473, in wsgi_app
    response = self.full_dispatch_request()
  File "/usr/local/lib/python3.10/dist-packages/flask/app.py", line 882, in full_dispatch_request
    rv = self.handle_user_exception(e)
  File "/usr/local/lib/python3.10/dist-packages/flask_cors/extension.py", line 194, in wrapped_function
    return cors_after_request(app.make_response(f(*args, **kwargs)))
  File "/usr/local/lib/python3.10/dist-packages/flask/app.py", line 880, in full_dispatch_request
    rv = self.dispatch_request()
  File "/usr/local/lib/python3.10/dist-packages/flask/app.py", line 865, in dispatch_request
    return self.ensure_sync(self.view_functions[rule.endpoint])(**view_args)  # type: ignore[no-any-return]
  File "/root/spysnet/website/views.py", line 563, in check_username
    if current_user.type != 'admin':
AttributeError: 'AnonymousUserMixin' object has no attribute 'type'
Traceback (most recent call last):
  File "/usr/local/lib/python3.10/dist-packages/flask/app.py", line 1498, in __call__
    return self.wsgi_app(environ, start_response)
  File "/usr/local/lib/python3.10/dist-packages/flask_socketio/__init__.py", line 43, in __call__
    return super(_SocketIOMiddleware, self).__call__(environ,
  File "/usr/local/lib/python3.10/dist-packages/engineio/middleware.py", line 74, in __call__
    return self.wsgi_app(environ, start_response)
  File "/usr/local/lib/python3.10/dist-packages/flask/app.py", line 1476, in wsgi_app
    response = self.handle_exception(e)
  File "/usr/local/lib/python3.10/dist-packages/flask_cors/extension.py", line 194, in wrapped_function
    return cors_after_request(app.make_response(f(*args, **kwargs)))
  File "/usr/local/lib/python3.10/dist-packages/flask/app.py", line 1473, in wsgi_app
    response = self.full_dispatch_request()
  File "/usr/local/lib/python3.10/dist-packages/flask/app.py", line 882, in full_dispatch_request
    rv = self.handle_user_exception(e)
  File "/usr/local/lib/python3.10/dist-packages/flask_cors/extension.py", line 194, in wrapped_function
    return cors_after_request(app.make_response(f(*args, **kwargs)))
  File "/usr/local/lib/python3.10/dist-packages/flask/app.py", line 880, in full_dispatch_request
    rv = self.dispatch_request()
  File "/usr/local/lib/python3.10/dist-packages/flask/app.py", line 865, in dispatch_request
    return self.ensure_sync(self.view_functions[rule.endpoint])(**view_args)  # type: ignore[no-any-return]
  File "/root/spysnet/website/views.py", line 563, in check_username
    if current_user.type != 'admin':
AttributeError: 'AnonymousUserMixin' object has no attribute 'type'
Traceback (most recent call last):
  File "/usr/local/lib/python3.10/dist-packages/flask/app.py", line 1498, in __call__
    return self.wsgi_app(environ, start_response)
  File "/usr/local/lib/python3.10/dist-packages/flask_socketio/__init__.py", line 43, in __call__
    return super(_SocketIOMiddleware, self).__call__(environ,
  File "/usr/local/lib/python3.10/dist-packages/engineio/middleware.py", line 74, in __call__
    return self.wsgi_app(environ, start_response)
  File "/usr/local/lib/python3.10/dist-packages/flask/app.py", line 1476, in wsgi_app
    response = self.handle_exception(e)
  File "/usr/local/lib/python3.10/dist-packages/flask_cors/extension.py", line 194, in wrapped_function
    return cors_after_request(app.make_response(f(*args, **kwargs)))
  File "/usr/local/lib/python3.10/dist-packages/flask/app.py", line 1473, in wsgi_app
    response = self.full_dispatch_request()
  File "/usr/local/lib/python3.10/dist-packages/flask/app.py", line 882, in full_dispatch_request
    rv = self.handle_user_exception(e)
  File "/usr/local/lib/python3.10/dist-packages/flask_cors/extension.py", line 194, in wrapped_function
    return cors_after_request(app.make_response(f(*args, **kwargs)))
  File "/usr/local/lib/python3.10/dist-packages/flask/app.py", line 880, in full_dispatch_request
    rv = self.dispatch_request()
  File "/usr/local/lib/python3.10/dist-packages/flask/app.py", line 865, in dispatch_request
    return self.ensure_sync(self.view_functions[rule.endpoint])(**view_args)  # type: ignore[no-any-return]
  File "/root/spysnet/website/views.py", line 563, in check_username
    if current_user.type != 'admin':
AttributeError: 'AnonymousUserMixin' object has no attribute 'type'
Traceback (most recent call last):
  File "/usr/local/lib/python3.10/dist-packages/flask/app.py", line 1498, in __call__
    return self.wsgi_app(environ, start_response)
  File "/usr/local/lib/python3.10/dist-packages/flask_socketio/__init__.py", line 43, in __call__
    return super(_SocketIOMiddleware, self).__call__(environ,
  File "/usr/local/lib/python3.10/dist-packages/engineio/middleware.py", line 74, in __call__
    return self.wsgi_app(environ, start_response)
  File "/usr/local/lib/python3.10/dist-packages/flask/app.py", line 1476, in wsgi_app
    response = self.handle_exception(e)
  File "/usr/local/lib/python3.10/dist-packages/flask_cors/extension.py", line 194, in wrapped_function
    return cors_after_request(app.make_response(f(*args, **kwargs)))
  File "/usr/local/lib/python3.10/dist-packages/flask/app.py", line 1473, in wsgi_app
    response = self.full_dispatch_request()
  File "/usr/local/lib/python3.10/dist-packages/flask/app.py", line 882, in full_dispatch_request
    rv = self.handle_user_exception(e)
  File "/usr/local/lib/python3.10/dist-packages/flask_cors/extension.py", line 194, in wrapped_function
    return cors_after_request(app.make_response(f(*args, **kwargs)))
  File "/usr/local/lib/python3.10/dist-packages/flask/app.py", line 880, in full_dispatch_request
    rv = self.dispatch_request()
  File "/usr/local/lib/python3.10/dist-packages/flask/app.py", line 865, in dispatch_request
    return self.ensure_sync(self.view_functions[rule.endpoint])(**view_args)  # type: ignore[no-any-return]
  File "/root/spysnet/website/views.py", line 563, in check_username
    if current_user.type != 'admin':
AttributeError: 'AnonymousUserMixin' object has no attribute 'type'
47.242.231.143 - - [02/Nov/2024 04:50:28] code 400, message Bad request version ('À\x13À')
Traceback (most recent call last):
  File "/usr/local/lib/python3.10/dist-packages/flask/app.py", line 1498, in __call__
    return self.wsgi_app(environ, start_response)
  File "/usr/local/lib/python3.10/dist-packages/flask_socketio/__init__.py", line 43, in __call__
    return super(_SocketIOMiddleware, self).__call__(environ,
  File "/usr/local/lib/python3.10/dist-packages/engineio/middleware.py", line 74, in __call__
    return self.wsgi_app(environ, start_response)
  File "/usr/local/lib/python3.10/dist-packages/flask/app.py", line 1476, in wsgi_app
    response = self.handle_exception(e)
  File "/usr/local/lib/python3.10/dist-packages/flask_cors/extension.py", line 194, in wrapped_function
    return cors_after_request(app.make_response(f(*args, **kwargs)))
  File "/usr/local/lib/python3.10/dist-packages/flask/app.py", line 1473, in wsgi_app
    response = self.full_dispatch_request()
  File "/usr/local/lib/python3.10/dist-packages/flask/app.py", line 882, in full_dispatch_request
    rv = self.handle_user_exception(e)
  File "/usr/local/lib/python3.10/dist-packages/flask_cors/extension.py", line 194, in wrapped_function
    return cors_after_request(app.make_response(f(*args, **kwargs)))
  File "/usr/local/lib/python3.10/dist-packages/flask/app.py", line 880, in full_dispatch_request
    rv = self.dispatch_request()
  File "/usr/local/lib/python3.10/dist-packages/flask/app.py", line 865, in dispatch_request
    return self.ensure_sync(self.view_functions[rule.endpoint])(**view_args)  # type: ignore[no-any-return]
  File "/root/spysnet/website/views.py", line 1008, in create_user_route
    new_user = User(
  File "<string>", line 4, in __init__
  File "/usr/local/lib/python3.10/dist-packages/sqlalchemy/orm/state.py", line 571, in _initialize_instance
    with util.safe_reraise():
  File "/usr/local/lib/python3.10/dist-packages/sqlalchemy/util/langhelpers.py", line 146, in __exit__
    raise exc_value.with_traceback(exc_tb)
  File "/usr/local/lib/python3.10/dist-packages/sqlalchemy/orm/state.py", line 569, in _initialize_instance
    manager.original_init(*mixed[1:], **kwargs)
  File "/usr/local/lib/python3.10/dist-packages/sqlalchemy/orm/decl_base.py", line 2167, in _declarative_constructor
    raise TypeError(
TypeError: 'created_by' is an invalid keyword argument for User
Traceback (most recent call last):
  File "/usr/local/lib/python3.10/dist-packages/flask/app.py", line 1498, in __call__
    return self.wsgi_app(environ, start_response)
  File "/usr/local/lib/python3.10/dist-packages/flask_socketio/__init__.py", line 43, in __call__
    return super(_SocketIOMiddleware, self).__call__(environ,
  File "/usr/local/lib/python3.10/dist-packages/engineio/middleware.py", line 74, in __call__
    return self.wsgi_app(environ, start_response)
  File "/usr/local/lib/python3.10/dist-packages/flask/app.py", line 1476, in wsgi_app
    response = self.handle_exception(e)
  File "/usr/local/lib/python3.10/dist-packages/flask_cors/extension.py", line 194, in wrapped_function
    return cors_after_request(app.make_response(f(*args, **kwargs)))
  File "/usr/local/lib/python3.10/dist-packages/flask/app.py", line 1473, in wsgi_app
    response = self.full_dispatch_request()
  File "/usr/local/lib/python3.10/dist-packages/flask/app.py", line 882, in full_dispatch_request
    rv = self.handle_user_exception(e)
  File "/usr/local/lib/python3.10/dist-packages/flask_cors/extension.py", line 194, in wrapped_function
    return cors_after_request(app.make_response(f(*args, **kwargs)))
  File "/usr/local/lib/python3.10/dist-packages/flask/app.py", line 880, in full_dispatch_request
    rv = self.dispatch_request()
  File "/usr/local/lib/python3.10/dist-packages/flask/app.py", line 865, in dispatch_request
    return self.ensure_sync(self.view_functions[rule.endpoint])(**view_args)  # type: ignore[no-any-return]
  File "/root/spysnet/website/views.py", line 992, in create_user_route
    new_user = User(
  File "<string>", line 4, in __init__
  File "/usr/local/lib/python3.10/dist-packages/sqlalchemy/orm/state.py", line 571, in _initialize_instance
    with util.safe_reraise():
  File "/usr/local/lib/python3.10/dist-packages/sqlalchemy/util/langhelpers.py", line 146, in __exit__
    raise exc_value.with_traceback(exc_tb)
  File "/usr/local/lib/python3.10/dist-packages/sqlalchemy/orm/state.py", line 569, in _initialize_instance
    manager.original_init(*mixed[1:], **kwargs)
  File "/usr/local/lib/python3.10/dist-packages/sqlalchemy/orm/decl_base.py", line 2167, in _declarative_constructor
    raise TypeError(
TypeError: 'created_by' is an invalid keyword argument for User
